Workbook

Sheet Summary
N3: Siap Drop | P3: PH SN | Q3: History PS | R3: =R6+R35 -> 0 | S3: Tgl Siap Drop | U3: Belum Siap Drop | W3: PH SN | X3: History PS | Y3: Examini | Z3: Pre
N4: Belum Drop | U4: 022D | V4: =VLOOKUP(U4,'Data Lokasi'!$C$13:$D$593,2,0) -> 8.24 | W4: =IFERROR(VLOOKUP(U4,[1]Master!$D$542:$K$1797,8,0),"-") -> 0 | X4: =IFERROR(VLOOKUP(U4,[1]Master!$D$542:$I$1797,6,0),"-") -> 0 | Y4: 0.5 | Z4: =VLOOKUP(U4,'Data Lokasi'!$C$13:$K$593,9,0) -> 44741 | AB4: =V4*Y4 -> 4.12
D5: Monitor Siap Tanam Nanas PG1 | N5: 022C | P5: =IFERROR(VLOOKUP(N5,[1]Master!$D$542:$K$1797,8,0),"-") -> 0 | Q5: =IFERROR(VLOOKUP(N5,[1]Master!$D$542:$I$1797,6,0),"-") -> 0 | R5: =IFERROR(VLOOKUP(N5,'Data Lokasi'!$C$13:$X$593,22,0),"-") -> 0 | S5: =IFERROR(VLOOKUP(N5,'Data Lokasi'!$C$13:$S$593,12,0),"-") -> 44749 | U5: 052C | V5: =VLOOKUP(U5,'Data Lokasi'!$C$13:$D$593,2,0) -> 8.54 | W5: =IFERROR(VLOOKUP(U5,[1]Master!$D$542:$K$1797,8,0),"-") -> 0 | X5: =IFERROR(VLOOKUP(U5,[1]Master!$D$542:$I$1797,6,0),"-") -> PS NS NS | Z5: =VLOOKUP(U5,'Data Lokasi'!$C$13:$K$593,9,0) -> 44747 | AB5: =V5*Y5 -> 0
N6: Total | R6: =SUM(R5:R5) -> 0 | S6: Ha | U6: 052D | V6: =VLOOKUP(U6,'Data Lokasi'!$C$13:$D$593,2,0) -> 10.04 | W6: =IFERROR(VLOOKUP(U6,[1]Master!$D$542:$K$1797,8,0),"-") -> 0 | X6: =IFERROR(VLOOKUP(U6,[1]Master!$D$542:$I$1797,6,0),"-") -> PS NS NS | Z6: =VLOOKUP(U6,'Data Lokasi'!$C$13:$K$593,9,0) -> 44747 | AB6: =V6*Y6 -> 0
N7: Sisa Proses Tanam | S7: Tgl Mulai Tanam | U7: 052E | V7: =VLOOKUP(U7,'Data Lokasi'!$C$13:$D$593,2,0) -> 11.4 | W7: =IFERROR(VLOOKUP(U7,[1]Master!$D$542:$K$1797,8,0),"-") -> 0 | X7: =IFERROR(VLOOKUP(U7,[1]Master!$D$542:$I$1797,6,0),"-") -> PS NS NS | Z7: =VLOOKUP(U7,'Data Lokasi'!$C$13:$K$593,9,0) -> 44747 | AB7: =V7*Y7 -> 0
H8: Update Per | J8: =+'Data Lokasi'!E4 -> 46308.615 | N8: 009F | P8: =IFERROR(VLOOKUP(N8,[1]Master!$D$542:$K$1797,8,0),"-") -> 4.52 | Q8: =IFERROR(VLOOKUP(N8,[1]Master!$D$542:$I$1797,6,0),"-") -> PS NS | R8: =VLOOKUP(N8,'Data Lokasi'!$C$13:$X$593,22,0) -> 0 | S8: =VLOOKUP(N8,'Data Lokasi'!$C$13:$S$593,17,0) -> 44713 | U8: 071D1 | V8: =VLOOKUP(U8,'Data Lokasi'!$C$13:$D$593,2,0) -> 4.57 | W8: =IFERROR(VLOOKUP(U8,[1]Master!$D$542:$K$1797,8,0),"-") -> 0 | X8: =IFERROR(VLOOKUP(U8,[1]Master!$D$542:$I$1797,6,0),"-") -> 0 | Y8: 0.3 | Z8: =VLOOKUP(U8,'Data Lokasi'!$C$13:$K$593,9,0) -> 44749 | AB8: =V8*Y8 -> 1.371
N9: 011B | O9: Excamini 70% | P9: =IFERROR(VLOOKUP(N9,[1]Master!$D$542:$K$1797,8,0),"-") -> 4.845 | Q9: =IFERROR(VLOOKUP(N9,[1]Master!$D$542:$I$1797,6,0),"-") -> PS | R9: =VLOOKUP(N9,'Data Lokasi'!$C$13:$X$593,22,0) -> 0 | S9: =VLOOKUP(N9,'Data Lokasi'!$C$13:$S$593,17,0) -> 44732 | U9: 075A | V9: =VLOOKUP(U9,'Data Lokasi'!$C$13:$D$593,2,0) -> 6.2 | W9: =IFERROR(VLOOKUP(U9,[1]Master!$D$542:$K$1797,8,0),"-") -> 0 | X9: =IFERROR(VLOOKUP(U9,[1]Master!$D$542:$I$1797,6,0),"-") -> PS NS NS | Z9: =VLOOKUP(U9,'Data Lokasi'!$C$13:$K$593,9,0) -> 44753 | AB9: =V9*Y9 -> 0
N10: 015B | O10: Excamini 0% | P10: =IFERROR(VLOOKUP(N10,[1]Master!$D$542:$K$1797,8,0),"-") -> 0 | Q10: =IFERROR(VLOOKUP(N10,[1]Master!$D$542:$I$1797,6,0),"-") -> 0 | R10: =VLOOKUP(N10,'Data Lokasi'!$C$13:$X$593,22,0) -> 0 | S10: =VLOOKUP(N10,'Data Lokasi'!$C$13:$S$593,17,0) -> 44748 | U10: 075F | V10: =VLOOKUP(U10,'Data Lokasi'!$C$13:$D$593,2,0) -> 9.58 | W10: =IFERROR(VLOOKUP(U10,[1]Master!$D$542:$K$1797,8,0),"-") -> 0 | X10: =IFERROR(VLOOKUP(U10,[1]Master!$D$542:$I$1797,6,0),"-") -> 0 | Z10: =VLOOKUP(U10,'Data Lokasi'!$C$13:$K$593,9,0) -> 44753 | AB10: =V10*Y10 -> 0
N11: 018D | P11: =IFERROR(VLOOKUP(N11,[1]Master!$D$542:$K$1797,8,0),"-") -> 4.895 | Q11: =IFERROR(VLOOKUP(N11,[1]Master!$D$542:$I$1797,6,0),"-") -> PS | R11: =VLOOKUP(N11,'Data Lokasi'!$C$13:$X$593,22,0) -> 0 | S11: =VLOOKUP(N11,'Data Lokasi'!$C$13:$S$593,17,0) -> 44737 | U11: 076H | V11: =VLOOKUP(U11,'Data Lokasi'!$C$13:$D$593,2,0) -> 6.34 | W11: =IFERROR(VLOOKUP(U11,[1]Master!$D$542:$K$1797,8,0),"-") -> 0 | X11: =IFERROR(VLOOKUP(U11,[1]Master!$D$542:$I$1797,6,0),"-") -> 0 | Y11: 0.9 | Z11: =VLOOKUP(U11,'Data Lokasi'!$C$13:$K$593,9,0) -> 44747 | AB11: =V11*Y11 -> 5.706
D12: Total Siap Nanas | J12: =SUM(J13:J17) -> 212.9 | K12: Ha | N12: 020A | P12: =IFERROR(VLOOKUP(N12,[1]Master!$D$542:$K$1797,8,0),"-") -> 4.955 | Q12: =IFERROR(VLOOKUP(N12,[1]Master!$D$542:$I$1797,6,0),"-") -> PS NS | R12: =VLOOKUP(N12,'Data Lokasi'!$C$13:$X$593,22,0) -> 0 | S12: =VLOOKUP(N12,'Data Lokasi'!$C$13:$S$593,17,0) -> 44710 | U12: 098G | V12: =VLOOKUP(U12,'Data Lokasi'!$C$13:$D$593,2,0) -> 7.14 | W12: =IFERROR(VLOOKUP(U12,[1]Master!$D$542:$K$1797,8,0),"-") -> 0 | X12: =IFERROR(VLOOKUP(U12,[1]Master!$D$542:$I$1797,6,0),"-") -> 0 | Z12: =VLOOKUP(U12,'Data Lokasi'!$C$13:$K$593,9,0) -> 44750 | AB12: =V12*Y12 -> 0
D13: - Siap Drop | J13: =R35+R6 -> 0 | K13: Ha | N13: 022B | P13: =IFERROR(VLOOKUP(N13,[1]Master!$D$542:$K$1797,8,0),"-") -> 0 | Q13: =IFERROR(VLOOKUP(N13,[1]Master!$D$542:$I$1797,6,0),"-") -> 0 | R13: =VLOOKUP(N13,'Data Lokasi'!$C$13:$X$593,22,0) -> 0 | S13: =VLOOKUP(N13,'Data Lokasi'!$C$13:$S$593,17,0) -> 44749 | U13: 098H | V13: =VLOOKUP(U13,'Data Lokasi'!$C$13:$D$593,2,0) -> 3.58 | W13: =IFERROR(VLOOKUP(U13,[1]Master!$D$542:$K$1797,8,0),"-") -> 4.59 | X13: =IFERROR(VLOOKUP(U13,[1]Master!$D$542:$I$1797,6,0),"-") -> 0 | Y13: 0.25 | Z13: =VLOOKUP(U13,'Data Lokasi'!$C$13:$K$593,9,0) -> 44750 | AB13: =V13*Y13 -> 0.895
D14: - SN Belum Siap Drop | N14: 025G | P14: =IFERROR(VLOOKUP(N14,[1]Master!$D$542:$K$1797,8,0),"-") -> 4.47 | Q14: =IFERROR(VLOOKUP(N14,[1]Master!$D$542:$I$1797,6,0),"-") -> 0 | R14: =VLOOKUP(N14,'Data Lokasi'!$C$13:$X$593,22,0) -> 0 | S14: =VLOOKUP(N14,'Data Lokasi'!$C$13:$S$593,17,0) -> 44705 | U14: Total | V14: =SUM(V4:V13) -> 75.63 | W14: Ha | AB14: =SUM(AB4:AB13) -> 12.092
E15: - Blm Pre Sudah Exca | J15: ='Data Lokasi'!Q6 -> 0 | K15: Ha | N15: 027C | O15: Excamini 50% | P15: =IFERROR(VLOOKUP(N15,[1]Master!$D$542:$K$1797,8,0),"-") -> 4.91 | Q15: =IFERROR(VLOOKUP(N15,[1]Master!$D$542:$I$1797,6,0),"-") -> 0 | R15: =VLOOKUP(N15,'Data Lokasi'!$C$13:$X$593,22,0) -> 0 | S15: =VLOOKUP(N15,'Data Lokasi'!$C$13:$S$593,17,0) -> 44735 | X15: * Kuning Berarti Masih Proses
E16: - Sudah Pre Blm Exca | J16: ='Data Lokasi'!Q7 -> 212.9 | K16: Ha | N16: 027F | O16: Excamini 0% | P16: =IFERROR(VLOOKUP(N16,[1]Master!$D$542:$K$1797,8,0),"-") -> 5.24 | Q16: =IFERROR(VLOOKUP(N16,[1]Master!$D$542:$I$1797,6,0),"-") -> 0 | R16: =VLOOKUP(N16,'Data Lokasi'!$C$13:$X$593,22,0) -> 0 | S16: =VLOOKUP(N16,'Data Lokasi'!$C$13:$S$593,17,0) -> 44738 | U16: Real Tanam s.d | V16: =J8-1 -> 46307.615 | AB16: =VLOOKUP(N8,'Data Lokasi'!$C$13:$D$593,2,0) -> 9.15 | AC16: 1 | AD16: =AC16*AB16 -> 9.15
E17: - Blm Pre Blm Exca | J17: ='Data Lokasi'!Q8 -> 0 | K17: Ha | N17: 027K | O17: Excamini 0% | P17: =IFERROR(VLOOKUP(N17,[1]Master!$D$542:$K$1797,8,0),"-") -> 4.725 | Q17: =IFERROR(VLOOKUP(N17,[1]Master!$D$542:$I$1797,6,0),"-") -> 0 | R17: =VLOOKUP(N17,'Data Lokasi'!$C$13:$X$593,22,0) -> 0 | S17: =VLOOKUP(N17,'Data Lokasi'!$C$13:$S$593,17,0) -> 44741 | U17: Hasil Tanam | V17: 0 | AB17: =VLOOKUP(N9,'Data Lokasi'!$C$13:$D$593,2,0) -> 6.57 | AC17: 0.7 | AD17: =AC17*AB17 -> 4.599
N18: 032D | O18: Excamini 60% | P18: =IFERROR(VLOOKUP(N18,[1]Master!$D$542:$K$1797,8,0),"-") -> 0 | Q18: =IFERROR(VLOOKUP(N18,[1]Master!$D$542:$I$1797,6,0),"-") -> 0 | R18: =VLOOKUP(N18,'Data Lokasi'!$C$13:$X$593,22,0) -> 0 | S18: =VLOOKUP(N18,'Data Lokasi'!$C$13:$S$593,17,0) -> 44745 | U18: Akum Tanam | V18: ='Data Lokasi'!G6 -> 51.15 | AB18: =VLOOKUP(N10,'Data Lokasi'!$C$13:$D$593,2,0) -> 5.44 | AC18: 0 | AD18: =AC18*AB18 -> 0
D19: Belum Siap Drop | N19: 039E | O19: Excamini 85% | P19: =IFERROR(VLOOKUP(N19,[1]Master!$D$542:$K$1797,8,0),"-") -> 4.6 | Q19: =IFERROR(VLOOKUP(N19,[1]Master!$D$542:$I$1797,6,0),"-") -> 0 | R19: =VLOOKUP(N19,'Data Lokasi'!$C$13:$X$593,22,0) -> 0 | S19: =VLOOKUP(N19,'Data Lokasi'!$C$13:$S$593,17,0) -> 44727 | AB19: =VLOOKUP(N11,'Data Lokasi'!$C$13:$D$593,2,0) -> 6.98 | AC19: 1 | AD19: =AC19*AB19 -> 6.98
D20: - Belum Examini | J20: =(V14-AB14)+(AB42-AD42) -> 91.0245 | K20: Ha | N20: 052G | P20: =IFERROR(VLOOKUP(N20,[1]Master!$D$542:$K$1797,8,0),"-") -> 4.275 | Q20: =IFERROR(VLOOKUP(N20,[1]Master!$D$542:$I$1797,6,0),"-") -> PS NS NS | R20: =VLOOKUP(N20,'Data Lokasi'!$C$13:$X$593,22,0) -> 0 | S20: =VLOOKUP(N20,'Data Lokasi'!$C$13:$S$593,17,0) -> 44723 | U20: Target Tanam | V20: 30 | AB20: =VLOOKUP(N12,'Data Lokasi'!$C$13:$D$593,2,0) -> 10.83 | AC20: 1 | AD20: =AC20*AB20 -> 10.83
D21: - Belum Pre | J21: ='Data Lokasi'!Q8+'Data Lokasi'!Q6 -> 0 | K21: Ha | N21: 055K | O21: Excamini 90% | P21: =IFERROR(VLOOKUP(N21,[1]Master!$D$542:$K$1797,8,0),"-") -> 4.7 | Q21: =IFERROR(VLOOKUP(N21,[1]Master!$D$542:$I$1797,6,0),"-") -> PS NS | R21: =VLOOKUP(N21,'Data Lokasi'!$C$13:$X$593,22,0) -> 0 | S21: =VLOOKUP(N21,'Data Lokasi'!$C$13:$S$593,17,0) -> 44726 | AB21: =VLOOKUP(N13,'Data Lokasi'!$C$13:$D$593,2,0) -> 6.87 | AC21: 1 | AD21: 0.2785
N22: 055K2 | O22: Excamini 90% | P22: =IFERROR(VLOOKUP(N22,[1]Master!$D$542:$K$1797,8,0),"-") -> 4.955 | Q22: =IFERROR(VLOOKUP(N22,[1]Master!$D$542:$I$1797,6,0),"-") -> PS NS | R22: =VLOOKUP(N22,'Data Lokasi'!$C$13:$X$593,22,0) -> 0 | S22: =VLOOKUP(N22,'Data Lokasi'!$C$13:$S$593,17,0) -> 44735 | U22: Sisa Target | V22: =-V20+V18 -> 21.15 | AB22: =VLOOKUP(N14,'Data Lokasi'!$C$13:$D$593,2,0) -> 8.41 | AC22: 0.5 | AD22: 0.2675
C23: * Total Siap Nanas = Sisa Proses Tanam + Belum Drop + Blm Exa + Blm Pre + Blm Pre & Exa | N23: 062G2 | P23: =IFERROR(VLOOKUP(N23,[1]Master!$D$542:$K$1797,8,0),"-") -> 4.445 | Q23: =IFERROR(VLOOKUP(N23,[1]Master!$D$542:$I$1797,6,0),"-") -> 0 | R23: =VLOOKUP(N23,'Data Lokasi'!$C$13:$X$593,22,0) -> 0 | S23: =VLOOKUP(N23,'Data Lokasi'!$C$13:$S$593,17,0) -> 44733 | AB23: =VLOOKUP(N15,'Data Lokasi'!$C$13:$D$593,2,0) -> 11.75 | AC23: 0 | AD23: 12.9485
N24: 067A | P24: =IFERROR(VLOOKUP(N24,[1]Master!$D$542:$K$1797,8,0),"-") -> 0 | Q24: =IFERROR(VLOOKUP(N24,[1]Master!$D$542:$I$1797,6,0),"-") -> PS NS NS NS | R24: =VLOOKUP(N24,'Data Lokasi'!$C$13:$X$593,22,0) -> 0 | S24: =VLOOKUP(N24,'Data Lokasi'!$C$13:$S$593,17,0) -> 44732 | AB24: =VLOOKUP(N16,'Data Lokasi'!$C$13:$D$593,2,0) -> 7.07 | AC24: 0 | AD24: 4.89
N25: 069C5 | P25: =IFERROR(VLOOKUP(N25,[1]Master!$D$542:$K$1797,8,0),"-") -> 4.845 | Q25: =IFERROR(VLOOKUP(N25,[1]Master!$D$542:$I$1797,6,0),"-") -> 0 | R25: =VLOOKUP(N25,'Data Lokasi'!$C$13:$X$593,22,0) -> 0 | S25: =VLOOKUP(N25,'Data Lokasi'!$C$13:$S$593,17,0) -> 44730 | U25: Stok Ridger | W25: Keterangan | AB25: =VLOOKUP(N17,'Data Lokasi'!$C$13:$D$593,2,0) -> 8.17 | AC25: 0.6 | AD25: 6.942
N26: 073A | P26: =IFERROR(VLOOKUP(N26,[1]Master!$D$542:$K$1797,8,0),"-") -> 4.815 | Q26: =IFERROR(VLOOKUP(N26,[1]Master!$D$542:$I$1797,6,0),"-") -> PS NT NS NS | R26: =VLOOKUP(N26,'Data Lokasi'!$C$13:$X$593,22,0) -> 0 | S26: =VLOOKUP(N26,'Data Lokasi'!$C$13:$S$593,17,0) -> 44748 | U26: 072F | V26: 9.84 | W26: Saluran Hari Ini | AB26: =VLOOKUP(N18,'Data Lokasi'!$C$13:$D$593,2,0) -> 8.45 | AC26: 0.85 | AD26: 0
N27: 076I | O27: Excamini 20% | P27: =IFERROR(VLOOKUP(N27,[1]Master!$D$542:$K$1797,8,0),"-") -> 0 | Q27: =IFERROR(VLOOKUP(N27,[1]Master!$D$542:$I$1797,6,0),"-") -> 0 | R27: =VLOOKUP(N27,'Data Lokasi'!$C$13:$X$593,22,0) -> 0 | S27: =VLOOKUP(N27,'Data Lokasi'!$C$13:$S$593,17,0) -> 44750 | U27: Total | V27: =SUM(V26:V26) -> 9.84 | AB27: =VLOOKUP(N19,'Data Lokasi'!$C$13:$D$593,2,0) -> 10.1 | AC27: 1 | AD27: 6.42
N28: 083A1 | P28: =IFERROR(VLOOKUP(N28,[1]Master!$D$542:$K$1797,8,0),"-") -> 4.425 | Q28: =IFERROR(VLOOKUP(N28,[1]Master!$D$542:$I$1797,6,0),"-") -> 0 | R28: =VLOOKUP(N28,'Data Lokasi'!$C$13:$X$593,22,0) -> 0 | S28: =VLOOKUP(N28,'Data Lokasi'!$C$13:$S$593,17,0) -> 44728 | AB28: =VLOOKUP(N20,'Data Lokasi'!$C$13:$D$593,2,0) -> 5.57 | AC28: 0.9 | AD28: 0
N29: 084D | P29: =IFERROR(VLOOKUP(N29,[1]Master!$D$542:$K$1797,8,0),"-") -> 4.785 | Q29: =IFERROR(VLOOKUP(N29,[1]Master!$D$542:$I$1797,6,0),"-") -> 0 | R29: =VLOOKUP(N29,'Data Lokasi'!$C$13:$X$593,22,0) -> 0 | S29: =VLOOKUP(N29,'Data Lokasi'!$C$13:$S$593,17,0) -> 44713 | AB29: =VLOOKUP(N21,'Data Lokasi'!$C$13:$D$593,2,0) -> 6.38 | AC29: 0.9 | AD29: 9.936
N30: 094C | P30: =IFERROR(VLOOKUP(N30,[1]Master!$D$542:$K$1797,8,0),"-") -> 4.58 | Q30: =IFERROR(VLOOKUP(N30,[1]Master!$D$542:$I$1797,6,0),"-") -> 0 | R30: =VLOOKUP(N30,'Data Lokasi'!$C$13:$X$593,22,0) -> 0 | S30: =VLOOKUP(N30,'Data Lokasi'!$C$13:$S$593,17,0) -> 44725 | AB30: =VLOOKUP(N22,'Data Lokasi'!$C$13:$D$593,2,0) -> 5.35 | AC30: 1 | AD30: 11.62
N31: 094H | P31: =IFERROR(VLOOKUP(N31,[1]Master!$D$542:$K$1797,8,0),"-") -> 4.825 | Q31: =IFERROR(VLOOKUP(N31,[1]Master!$D$542:$I$1797,6,0),"-") -> 0 | R31: =VLOOKUP(N31,'Data Lokasi'!$C$13:$X$593,22,0) -> 0 | S31: =VLOOKUP(N31,'Data Lokasi'!$C$13:$S$593,17,0) -> 44726 | AB31: =VLOOKUP(N23,'Data Lokasi'!$C$13:$D$593,2,0) -> 4.89 | AC31: 1 | AD31: 8.21
N32: 094B1 | P32: =IFERROR(VLOOKUP(N32,[1]Master!$D$542:$K$1797,8,0),"-") -> 4.56 | Q32: =IFERROR(VLOOKUP(N32,[1]Master!$D$542:$I$1797,6,0),"-") -> 0 | R32: =VLOOKUP(N32,'Data Lokasi'!$C$13:$X$593,22,0) -> 0 | S32: =VLOOKUP(N32,'Data Lokasi'!$C$13:$S$593,17,0) -> 44737 | AB32: =VLOOKUP(N24,'Data Lokasi'!$C$13:$D$593,2,0) -> 11.57 | AC32: 1 | AD32: 7.49
N33: 095D | P33: =IFERROR(VLOOKUP(N33,[1]Master!$D$542:$K$1797,8,0),"-") -> 4.46 | Q33: =IFERROR(VLOOKUP(N33,[1]Master!$D$542:$I$1797,6,0),"-") -> 0 | R33: =VLOOKUP(N33,'Data Lokasi'!$C$13:$X$593,22,0) -> 0 | S33: =VLOOKUP(N33,'Data Lokasi'!$C$13:$S$593,17,0) -> 44749 | AB33: =VLOOKUP(N25,'Data Lokasi'!$C$13:$D$593,2,0) -> 10.05 | AC33: 1 | AD33: 3.796
N34: 097A1 | P34: =IFERROR(VLOOKUP(N34,[1]Master!$D$542:$K$1797,8,0),"-") -> 4.525 | Q34: =IFERROR(VLOOKUP(N34,[1]Master!$D$542:$I$1797,6,0),"-") -> 0 | R34: =VLOOKUP(N34,'Data Lokasi'!$C$13:$X$593,22,0) -> 0 | S34: =VLOOKUP(N34,'Data Lokasi'!$C$13:$S$593,17,0) -> 44721 | AB34: =VLOOKUP(N26,'Data Lokasi'!$C$13:$D$593,2,0) -> 6.42 | AC34: 1 | AD34: 7.19
N35: Total | R35: =SUM(R8:R34) -> 0 | S35: Ha | AB35: =VLOOKUP(N27,'Data Lokasi'!$C$13:$D$593,2,0) -> 5.48 | AC35: 0.2 | AD35: 8.14
R36: * Proses Tanam per | S36: =J8-1 -> 46307.615 | AB36: =VLOOKUP(N28,'Data Lokasi'!$C$13:$D$593,2,0) -> 3.44 | AC36: 1 | AD36: 7.51
N37: Siap Drop | R37: Wil. Timur | S37: Wil. Barat | AB37: =VLOOKUP(N29,'Data Lokasi'!$C$13:$D$593,2,0) -> 12.42 | AC37: 1 | AD37: 10.242
N38: Belum Drop | R38: =SUM(R5:R5) -> 0 | AB38: =VLOOKUP(N30,'Data Lokasi'!$C$13:$D$593,2,0) -> 8.21 | AC38: 1 | AD38: 10.242
N39: Sisa Proses Tanam | R39: =SUM(R8:R23) -> 0 | S39: =SUM(R24:R34) -> 0 | AB39: =VLOOKUP(N31,'Data Lokasi'!$C$13:$D$593,2,0) -> 5.84 | AC39: 1 | AD39: 10.242
N40: Sub Total | R40: =SUM(R38:R39) -> 0 | S40: =SUM(S38:S39) -> 0
N41: Total | R41: =SUM(R40:S40) -> 0 | S41: Ha
AB42: =SUM(AB16:AB41) -> 185.41 | AD42: =SUM(AD16:AD41) -> 157.9235

Sheet Data Lokasi
A1: s | I1: 9 | K1: 9 | S1: 17 | T1: 18
B2: Monitor Siap Nanas PG1
B4: Total Lhn Siap Tnm | D4: Per | E4: =NOW() -> 46308.615 | G4: =G9+Q9 -> 228.54 | I4: Ha
B5: Siap Tanam ( Sudah Pre + Examini ) | K5: Siap Tanam ( Belum Pre + Examini )
B6: - Sudah Tanam Bulan Ini | G6: =SUMPRODUCT($W$14:$W$2288,$R$14:$R$2288) -> 51.15 | I6: Ha | K6: - Belum Pre | Q6: =SUMPRODUCT($X$1:$X$2288,$L$1:$L$2288)-Q8 -> 0 | S6: Ha
B7: - Sisa Proses Tanam | G7: =SUMPRODUCT($X$14:$X$2288,$R$14:$R$2288) -> 15.64 | I7: Ha | K7: - Belum Examini | Q7: =SUMPRODUCT($X$1:$X$2288,$J$1:$J$2288)-SUMPRODUCT($X:$X,$M:$M) -> 212.9 | S7: Ha
B8: - Siap Drop | G8: =SUMPRODUCT($X$14:$X$2288,$O$14:$O$2288)-SUMPRODUCT($X$14:$X$2288,$R$14:$R$2288) -> 0 | I8: Ha | K8: - Belum Pre dan examini | Q8: =SUMPRODUCT($X2:$X2287,$M2:$M2287) -> 0 | S8: Ha
B9: Sub Total | G9: =SUM(G7:G8) -> 15.64 | I9: Ha | K9: Sub Total | Q9: =SUM(Q6:Q8) -> 212.9 | S9: Ha | AR9: ALL
B11: * Kuning berarti Masih Proses | G11: * Total Siap Nanas = Sisa Proses Tanam + Siap Drop + Blm Exa + Blm Pre + Blm Pre & Exa | V11: * Orange rencana selesai bulan ini | AH11: Hasil Inputan Laporan Mandor | AR11: Update Dari Mbak Mimin | AU11: BARAT | AX11: TOTAL | BA11: Update
B13: Wil. | C13: Lokasi | D13: Netto | E13: Ridger | G13: Jln & Saluran | I13: Examini | K13: Pree | N13: Siap Drop | Q13: Selesai Tanam | S13: Tgl Mulai Tanam | T13: Tgl Selesai Tanam | V13: Luas Sudah Tanam All | W13: Tanam Bulan Ini | X13: Sisa lahan | Y13: Eks | Z13: Tanam % | AA13: Tanggal Dolomite | AB13: Hari Stlh Dolomite | AC13: Peta | AD13: Tgl Selesai Tanam | AF13: Akum sd 12 Okt | AG13: RTN 12 | AH13: 46307 | AI13: =AH13+1 -> 46308 | AJ13: =AI13+1 -> 46309 | AK13: =AJ13+1 -> 46310 | AL13: =AK13+1 -> 46311 | AM13: =AL13+1 -> 46312 | AO13: Akum sd Sekarang | AP13: Manual | AR13: RTN 12 | AS13: Selisih | AU13: RTN 11 | AV13: Selisih | AX13: RTN 12 | AY13: Selisih | BA13: Lokasi Asal Bibit
B15: W01 | C15: 002A2 | D15: 6.02 | E15: 46253 | G15: 46254 | I15: =+G15 -> 46254 | J15: =IF(I15>0,0,1) -> 0 | K15: 46268 | M15: =IF(AND(J15>0,L15>0),1,0) -> 0 | N15: =IF(AND(I15>0,K15>0),MAX(I15:K15)+1,"") -> 46269 | O15: =IF(N15>0,1,0) -> 1 | P15: =IF(O15>0,0,1) -> 0 | Q15: =IF(T15>0,"Selesai","Proses") -> Proses | R15: =IF(Q15="proses",1,0) -> 1 | S15: 46271 | V15: =AO15 -> 6.02 | W15: =AP15 -> 0.05 | X15: =IF(G15=0,"",D15-V15) -> -8.8817842e-16 | Y15: =VLOOKUP($C15,[2]Nanas!$C$1336:$G$1420,5,0) -> PS | Z15: =1-X15/D15 -> 1 | AC15: Sudah | AD15: 46296 | AF15: =IFERROR(VLOOKUP($C15,[3]Real!$B$11:$Y$28,20,0),"") -> 6.02 | AG15: =IFERROR(VLOOKUP($C15,[3]Real!$B$11:$Y$28,18,0),"") -> 0.05 | AH15: =SUMIFS('Input Real Tanam&Petik Nanas'!$J:$J,'Input Real Tanam&Petik Nanas'!$C:$C,$C15,'Input Real Tanam&Petik Nanas'!$B:$B,'Data Lokasi'!AH$13) -> 0 | AI15: =SUMIFS('Input Real Tanam&Petik Nanas'!$J:$J,'Input Real Tanam&Petik Nanas'!$C:$C,$C15,'Input Real Tanam&Petik Nanas'!$B:$B,'Data Lokasi'!AI$13) -> 0 | AJ15: =SUMIFS('Input Real Tanam&Petik Nanas'!$J:$J,'Input Real Tanam&Petik Nanas'!$C:$C,$C15,'Input Real Tanam&Petik Nanas'!$B:$B,'Data Lokasi'!AJ$13) -> 0 | AK15: =SUMIFS('Input Real Tanam&Petik Nanas'!$J:$J,'Input Real Tanam&Petik Nanas'!$C:$C,$C15,'Input Real Tanam&Petik Nanas'!$B:$B,'Data Lokasi'!AK$13) -> 0 | AL15: =SUMIFS('Input Real Tanam&Petik Nanas'!$J:$J,'Input Real Tanam&Petik Nanas'!$C:$C,$C15,'Input Real Tanam&Petik Nanas'!$B:$B,'Data Lokasi'!AL$13) -> 0 | AM15: =SUMIFS('Input Real Tanam&Petik Nanas'!$J:$J,'Input Real Tanam&Petik Nanas'!$C:$C,$C15,'Input Real Tanam&Petik Nanas'!$B:$B,'Data Lokasi'!AM$13) -> 0 | AO15: =IFERROR(AF15+AI15+AJ15+AK15+AL15+AM15,"") -> 6.02 | AP15: =IFERROR(AG15+AI15+AJ15+AK15+AL15+AM15,"") -> 0.05 | AR15: =IFERROR(VLOOKUP($C15,[3]Real!$B$11:$Y$28,18,0),"") -> 0.05 | AS15: =IFERROR(IF(AR15-AP15=0,"",(AR15-AP15)),"") | BA15: 055F1,032A,031B1,031B2
B16: W02 | C16: 024B | D16: 8.76 | E16: 46244 | G16: 46245 | I16: =+G16 -> 46245 | J16: =IF(I16>0,0,1) -> 0 | K16: 46269 | M16: =IF(AND(J16>0,L16>0),1,0) -> 0 | N16: =IF(AND(I16>0,K16>0),MAX(I16:K16)+1,"") -> 46270 | O16: =IF(N16>0,1,0) -> 1 | P16: =IF(O16>0,0,1) -> 0 | Q16: =IF(T16>0,"Selesai","Proses") -> Proses | R16: =IF(Q16="proses",1,0) -> 1 | S16: 46281 | V16: =AO16 -> 8.76 | W16: =AP16 -> 0.05 | X16: =IF(G16=0,"",D16-V16) -> 0 | Y16: =VLOOKUP($C16,[4]Nanas!$C$1336:$G$1416,5,0) -> RC | Z16: =1-X16/D16 -> 1 | AA16: =INDEX([5]Nanas!$M$1336:$M$1444,MATCH($C16,[5]Nanas!$C$1336:$C$1444,0)) -> 46205 | AB16: =S16-AA16 -> 76 | AC16: Sudah | AF16: =IFERROR(VLOOKUP($C16,[3]Real!$B$11:$Y$28,20,0),"") -> 8.76 | AG16: =IFERROR(VLOOKUP($C16,[3]Real!$B$11:$Y$28,18,0),"") -> 0.05 | AH16: =SUMIFS('Input Real Tanam&Petik Nanas'!$J:$J,'Input Real Tanam&Petik Nanas'!$C:$C,$C16,'Input Real Tanam&Petik Nanas'!$B:$B,'Data Lokasi'!AH$13) -> 0 | AI16: =SUMIFS('Input Real Tanam&Petik Nanas'!$J:$J,'Input Real Tanam&Petik Nanas'!$C:$C,$C16,'Input Real Tanam&Petik Nanas'!$B:$B,'Data Lokasi'!AI$13) -> 0 | AJ16: =SUMIFS('Input Real Tanam&Petik Nanas'!$J:$J,'Input Real Tanam&Petik Nanas'!$C:$C,$C16,'Input Real Tanam&Petik Nanas'!$B:$B,'Data Lokasi'!AJ$13) -> 0 | AK16: =SUMIFS('Input Real Tanam&Petik Nanas'!$J:$J,'Input Real Tanam&Petik Nanas'!$C:$C,$C16,'Input Real Tanam&Petik Nanas'!$B:$B,'Data Lokasi'!AK$13) -> 0 | AL16: =SUMIFS('Input Real Tanam&Petik Nanas'!$J:$J,'Input Real Tanam&Petik Nanas'!$C:$C,$C16,'Input Real Tanam&Petik Nanas'!$B:$B,'Data Lokasi'!AL$13) -> 0 | AM16: =SUMIFS('Input Real Tanam&Petik Nanas'!$J:$J,'Input Real Tanam&Petik Nanas'!$C:$C,$C16,'Input Real Tanam&Petik Nanas'!$B:$B,'Data Lokasi'!AM$13) -> 0 | AO16: =IFERROR(AF16+AI16+AJ16+AK16+AL16+AM16,"") -> 8.76 | AP16: =IFERROR(AG16+AI16+AJ16+AK16+AL16+AM16,"") -> 0.05 | AR16: =IFERROR(VLOOKUP($C16,[3]Real!$B$11:$Y$28,18,0),"") -> 0.05 | AS16: =IFERROR(IF(AR16-AP16=0,"",(AR16-AP16)),"") | BA16: 080F9,030C,066Q
B17: W06 | C17: 078I | D17: 5.05 | E17: 46262 | G17: 46263 | I17: =+G17 -> 46263 | J17: =IF(I17>0,0,1) -> 0 | K17: 46270 | M17: =IF(AND(J17>0,L17>0),1,0) -> 0 | N17: =IF(AND(I17>0,K17>0),MAX(I17:K17)+1,"") -> 46271 | O17: =IF(N17>0,1,0) -> 1 | P17: =IF(O17>0,0,1) -> 0 | Q17: =IF(T17>0,"Selesai","Proses") -> Proses | R17: =IF(Q17="proses",1,0) -> 1 | S17: 46276 | V17: =AO17 -> 5.05 | W17: =AP17 -> 0.25 | X17: =IF(G17=0,"",D17-V17) -> 0 | Y17: RC | Z17: =1-X17/D17 -> 1 | AA17: =INDEX([5]Nanas!$M$1336:$M$1444,MATCH($C17,[5]Nanas!$C$1336:$C$1444,0)) -> 46230 | AB17: =S17-AA17 -> 46 | AC17: Sudah | AF17: =IFERROR(VLOOKUP($C17,[3]Real!$B$11:$Y$28,20,0),"") -> 5.05 | AG17: =IFERROR(VLOOKUP($C17,[3]Real!$B$11:$Y$28,18,0),"") -> 0.25 | AH17: =SUMIFS('Input Real Tanam&Petik Nanas'!$J:$J,'Input Real Tanam&Petik Nanas'!$C:$C,$C17,'Input Real Tanam&Petik Nanas'!$B:$B,'Data Lokasi'!AH$13) -> 0 | AI17: =SUMIFS('Input Real Tanam&Petik Nanas'!$J:$J,'Input Real Tanam&Petik Nanas'!$C:$C,$C17,'Input Real Tanam&Petik Nanas'!$B:$B,'Data Lokasi'!AI$13) -> 0 | AJ17: =SUMIFS('Input Real Tanam&Petik Nanas'!$J:$J,'Input Real Tanam&Petik Nanas'!$C:$C,$C17,'Input Real Tanam&Petik Nanas'!$B:$B,'Data Lokasi'!AJ$13) -> 0 | AK17: =SUMIFS('Input Real Tanam&Petik Nanas'!$J:$J,'Input Real Tanam&Petik Nanas'!$C:$C,$C17,'Input Real Tanam&Petik Nanas'!$B:$B,'Data Lokasi'!AK$13) -> 0 | AL17: =SUMIFS('Input Real Tanam&Petik Nanas'!$J:$J,'Input Real Tanam&Petik Nanas'!$C:$C,$C17,'Input Real Tanam&Petik Nanas'!$B:$B,'Data Lokasi'!AL$13) -> 0 | AM17: =SUMIFS('Input Real Tanam&Petik Nanas'!$J:$J,'Input Real Tanam&Petik Nanas'!$C:$C,$C17,'Input Real Tanam&Petik Nanas'!$B:$B,'Data Lokasi'!AM$13) -> 0 | AO17: =IFERROR(AF17+AI17+AJ17+AK17+AL17+AM17,"") -> 5.05 | AP17: =IFERROR(AG17+AI17+AJ17+AK17+AL17+AM17,"") -> 0.25 | AR17: =IFERROR(VLOOKUP($C17,[3]Real!$B$11:$Y$28,18,0),"") -> 0.25 | AS17: =IFERROR(IF(AR17-AP17=0,"",(AR17-AP17)),"") | BA17: 094F,089E,089F,096J2
B18: W03 | C18: 061E1 | D18: 3.85 | E18: 46272 | G18: 46273 | I18: =+G18 -> 46273 | J18: =IF(I18>0,0,1) -> 0 | K18: 46283 | M18: =IF(AND(J18>0,L18>0),1,0) -> 0 | N18: =IF(AND(I18>0,K18>0),MAX(I18:K18)+1,"") -> 46284 | O18: =IF(N18>0,1,0) -> 1 | P18: =IF(O18>0,0,1) -> 0 | Q18: =IF(T18>0,"Selesai","Proses") -> Proses | R18: =IF(Q18="proses",1,0) -> 1 | S18: 46288 | V18: =AO18 -> 3.85 | W18: =AP18 -> 0.03 | X18: =IF(G18=0,"",D18-V18) -> 4.4408921e-16 | Y18: =INDEX([6]Nanas!$G$1429:$G$1436,MATCH($C18,[6]Nanas!$C$1429:$C$1436,0)) -> RC | Z18: =1-X18/D18 -> 1 | AA18: =INDEX([5]Nanas!$M$1336:$M$1444,MATCH($C18,[5]Nanas!$C$1336:$C$1444,0)) -> 46205 | AB18: =$E$4-AA18 -> 103.61513 | AC18: Sudah | AF18: =IFERROR(VLOOKUP($C18,[3]Real!$B$11:$Y$28,20,0),"") -> 3.85 | AG18: =IFERROR(VLOOKUP($C18,[3]Real!$B$11:$Y$28,18,0),"") -> 0.03 | AH18: =SUMIFS('Input Real Tanam&Petik Nanas'!$J:$J,'Input Real Tanam&Petik Nanas'!$C:$C,$C18,'Input Real Tanam&Petik Nanas'!$B:$B,'Data Lokasi'!AH$13) -> 0 | AI18: =SUMIFS('Input Real Tanam&Petik Nanas'!$J:$J,'Input Real Tanam&Petik Nanas'!$C:$C,$C18,'Input Real Tanam&Petik Nanas'!$B:$B,'Data Lokasi'!AI$13) -> 0 | AJ18: =SUMIFS('Input Real Tanam&Petik Nanas'!$J:$J,'Input Real Tanam&Petik Nanas'!$C:$C,$C18,'Input Real Tanam&Petik Nanas'!$B:$B,'Data Lokasi'!AJ$13) -> 0 | AK18: =SUMIFS('Input Real Tanam&Petik Nanas'!$J:$J,'Input Real Tanam&Petik Nanas'!$C:$C,$C18,'Input Real Tanam&Petik Nanas'!$B:$B,'Data Lokasi'!AK$13) -> 0 | AL18: =SUMIFS('Input Real Tanam&Petik Nanas'!$J:$J,'Input Real Tanam&Petik Nanas'!$C:$C,$C18,'Input Real Tanam&Petik Nanas'!$B:$B,'Data Lokasi'!AL$13) -> 0 | AM18: =SUMIFS('Input Real Tanam&Petik Nanas'!$J:$J,'Input Real Tanam&Petik Nanas'!$C:$C,$C18,'Input Real Tanam&Petik Nanas'!$B:$B,'Data Lokasi'!AM$13) -> 0 | AO18: =IFERROR(AF18+AI18+AJ18+AK18+AL18+AM18,"") -> 3.85 | AP18: =IFERROR(AG18+AI18+AJ18+AK18+AL18+AM18,"") -> 0.03 | AR18: =IFERROR(VLOOKUP($C18,[3]Real!$B$11:$Y$28,18,0),"") -> 0.03 | AS18: =IFERROR(IF(AR18-AP18=0,"",(AR18-AP18)),"") | BA18: 003A,005D,059D
B19: W03 | C19: 061E2 | D19: 6.01 | E19: 46272 | G19: 46273 | I19: =+G19 -> 46273 | J19: =IF(I19>0,0,1) -> 0 | K19: 46283 | M19: =IF(AND(J19>0,L19>0),1,0) -> 0 | N19: =IF(AND(I19>0,K19>0),MAX(I19:K19)+1,"") -> 46284 | O19: =IF(N19>0,1,0) -> 1 | P19: =IF(O19>0,0,1) -> 0 | Q19: =IF(T19>0,"Selesai","Proses") -> Proses | R19: =IF(Q19="proses",1,0) -> 1 | S19: 46291 | V19: =AO19 -> 6.01 | W19: =AP19 -> 0.12 | X19: =IF(G19=0,"",D19-V19) -> -8.8817842e-16 | Y19: =INDEX([6]Nanas!$G$1429:$G$1436,MATCH($C19,[6]Nanas!$C$1429:$C$1436,0)) -> RC | Z19: =1-X19/D19 -> 1 | AA19: =INDEX([5]Nanas!$M$1336:$M$1444,MATCH($C19,[5]Nanas!$C$1336:$C$1444,0)) -> 46238 | AB19: =$E$4-AA19 -> 70.615134 | AC19: Sudah | AF19: =IFERROR(VLOOKUP($C19,[3]Real!$B$11:$Y$28,20,0),"") -> 6.01 | AG19: =IFERROR(VLOOKUP($C19,[3]Real!$B$11:$Y$28,18,0),"") -> 0.12 | AH19: =SUMIFS('Input Real Tanam&Petik Nanas'!$J:$J,'Input Real Tanam&Petik Nanas'!$C:$C,$C19,'Input Real Tanam&Petik Nanas'!$B:$B,'Data Lokasi'!AH$13) -> 0 | AI19: =SUMIFS('Input Real Tanam&Petik Nanas'!$J:$J,'Input Real Tanam&Petik Nanas'!$C:$C,$C19,'Input Real Tanam&Petik Nanas'!$B:$B,'Data Lokasi'!AI$13) -> 0 | AJ19: =SUMIFS('Input Real Tanam&Petik Nanas'!$J:$J,'Input Real Tanam&Petik Nanas'!$C:$C,$C19,'Input Real Tanam&Petik Nanas'!$B:$B,'Data Lokasi'!AJ$13) -> 0 | AK19: =SUMIFS('Input Real Tanam&Petik Nanas'!$J:$J,'Input Real Tanam&Petik Nanas'!$C:$C,$C19,'Input Real Tanam&Petik Nanas'!$B:$B,'Data Lokasi'!AK$13) -> 0 | AL19: =SUMIFS('Input Real Tanam&Petik Nanas'!$J:$J,'Input Real Tanam&Petik Nanas'!$C:$C,$C19,'Input Real Tanam&Petik Nanas'!$B:$B,'Data Lokasi'!AL$13) -> 0 | AM19: =SUMIFS('Input Real Tanam&Petik Nanas'!$J:$J,'Input Real Tanam&Petik Nanas'!$C:$C,$C19,'Input Real Tanam&Petik Nanas'!$B:$B,'Data Lokasi'!AM$13) -> 0 | AO19: =IFERROR(AF19+AI19+AJ19+AK19+AL19+AM19,"") -> 6.01 | AP19: =IFERROR(AG19+AI19+AJ19+AK19+AL19+AM19,"") -> 0.12 | AR19: =IFERROR(VLOOKUP($C19,[3]Real!$B$11:$Y$28,18,0),"") -> 0.12 | AS19: =IFERROR(IF(AR19-AP19=0,"",(AR19-AP19)),"") | BA19: 062F1,062M,052A
B20: W03 | C20: 063E | D20: 6.45 | E20: 46279 | G20: 46280 | I20: =+G20 -> 46280 | J20: =IF(I20>0,0,1) -> 0 | K20: 46289 | M20: =IF(AND(J20>0,L20>0),1,0) -> 0 | N20: =IF(AND(I20>0,K20>0),MAX(I20:K20)+1,"") -> 46290 | O20: =IF(N20>0,1,0) -> 1 | P20: =IF(O20>0,0,1) -> 0 | Q20: =IF(T20>0,"Selesai","Proses") -> Proses | R20: =IF(Q20="proses",1,0) -> 1 | S20: 46299 | V20: =AO20 -> 6.45 | W20: =AP20 -> 6.45 | X20: =IF(G20=0,"",D20-V20) -> -8.8817842e-16 | Y20: RC | Z20: =1-X20/D20 -> 1 | AA20: =INDEX([5]Nanas!$M$1336:$M$1444,MATCH($C20,[5]Nanas!$C$1336:$C$1444,0)) -> 46242 | AB20: =$E$4-AA20 -> 66.615134 | AC20: Sudah | AF20: =IFERROR(VLOOKUP($C20,[3]Real!$B$11:$Y$28,20,0),"") -> 6.45 | AG20: =IFERROR(VLOOKUP($C20,[3]Real!$B$11:$Y$28,18,0),"") -> 6.45 | AH20: =SUMIFS('Input Real Tanam&Petik Nanas'!$J:$J,'Input Real Tanam&Petik Nanas'!$C:$C,$C20,'Input Real Tanam&Petik Nanas'!$B:$B,'Data Lokasi'!AH$13) -> 0.22 | AI20: =SUMIFS('Input Real Tanam&Petik Nanas'!$J:$J,'Input Real Tanam&Petik Nanas'!$C:$C,$C20,'Input Real Tanam&Petik Nanas'!$B:$B,'Data Lokasi'!AI$13) -> 0 | AJ20: =SUMIFS('Input Real Tanam&Petik Nanas'!$J:$J,'Input Real Tanam&Petik Nanas'!$C:$C,$C20,'Input Real Tanam&Petik Nanas'!$B:$B,'Data Lokasi'!AJ$13) -> 0 | AK20: =SUMIFS('Input Real Tanam&Petik Nanas'!$J:$J,'Input Real Tanam&Petik Nanas'!$C:$C,$C20,'Input Real Tanam&Petik Nanas'!$B:$B,'Data Lokasi'!AK$13) -> 0 | AL20: =SUMIFS('Input Real Tanam&Petik Nanas'!$J:$J,'Input Real Tanam&Petik Nanas'!$C:$C,$C20,'Input Real Tanam&Petik Nanas'!$B:$B,'Data Lokasi'!AL$13) -> 0 | AM20: =SUMIFS('Input Real Tanam&Petik Nanas'!$J:$J,'Input Real Tanam&Petik Nanas'!$C:$C,$C20,'Input Real Tanam&Petik Nanas'!$B:$B,'Data Lokasi'!AM$13) -> 0 | AO20: =IFERROR(AF20+AI20+AJ20+AK20+AL20+AM20,"") -> 6.45 | AP20: =IFERROR(AG20+AI20+AJ20+AK20+AL20+AM20,"") -> 6.45 | AR20: =IFERROR(VLOOKUP($C20,[3]Real!$B$11:$Y$28,18,0),"") -> 6.45 | AS20: =IFERROR(IF(AR20-AP20=0,"",(AR20-AP20)),"") | BA20: 004C2,046E,038D1,004C3,038D1
B21: W03 | C21: 064B | D21: 4.19 | E21: 46279 | G21: 46280 | I21: =+G21 -> 46280 | J21: =IF(I21>0,0,1) -> 0 | K21: 46289 | M21: =IF(AND(J21>0,L21>0),1,0) -> 0 | N21: =IF(AND(I21>0,K21>0),MAX(I21:K21)+1,"") -> 46290 | O21: =IF(N21>0,1,0) -> 1 | P21: =IF(O21>0,0,1) -> 0 | Q21: =IF(T21>0,"Selesai","Proses") -> Proses | R21: =IF(Q21="proses",1,0) -> 1 | S21: 46295 | V21: =AO21 -> 4.19 | W21: =AP21 -> 3.72 | X21: =IF(G21=0,"",D21-V21) -> 8.8817842e-16 | Y21: RC | Z21: =1-X21/D21 -> 1 | AA21: =INDEX([5]Nanas!$M$1336:$M$1444,MATCH($C21,[5]Nanas!$C$1336:$C$1444,0)) -> 46242 | AB21: =$E$4-AA21 -> 66.615134 | AC21: Sudah | AF21: =IFERROR(VLOOKUP($C21,[3]Real!$B$11:$Y$28,20,0),"") -> 4.19 | AG21: =IFERROR(VLOOKUP($C21,[3]Real!$B$11:$Y$28,18,0),"") -> 3.72 | AH21: =SUMIFS('Input Real Tanam&Petik Nanas'!$J:$J,'Input Real Tanam&Petik Nanas'!$C:$C,$C21,'Input Real Tanam&Petik Nanas'!$B:$B,'Data Lokasi'!AH$13) -> 0.42 | AI21: =SUMIFS('Input Real Tanam&Petik Nanas'!$J:$J,'Input Real Tanam&Petik Nanas'!$C:$C,$C21,'Input Real Tanam&Petik Nanas'!$B:$B,'Data Lokasi'!AI$13) -> 0 | AJ21: =SUMIFS('Input Real Tanam&Petik Nanas'!$J:$J,'Input Real Tanam&Petik Nanas'!$C:$C,$C21,'Input Real Tanam&Petik Nanas'!$B:$B,'Data Lokasi'!AJ$13) -> 0 | AK21: =SUMIFS('Input Real Tanam&Petik Nanas'!$J:$J,'Input Real Tanam&Petik Nanas'!$C:$C,$C21,'Input Real Tanam&Petik Nanas'!$B:$B,'Data Lokasi'!AK$13) -> 0 | AL21: =SUMIFS('Input Real Tanam&Petik Nanas'!$J:$J,'Input Real Tanam&Petik Nanas'!$C:$C,$C21,'Input Real Tanam&Petik Nanas'!$B:$B,'Data Lokasi'!AL$13) -> 0 | AM21: =SUMIFS('Input Real Tanam&Petik Nanas'!$J:$J,'Input Real Tanam&Petik Nanas'!$C:$C,$C21,'Input Real Tanam&Petik Nanas'!$B:$B,'Data Lokasi'!AM$13) -> 0 | AO21: =IFERROR(AF21+AI21+AJ21+AK21+AL21+AM21,"") -> 4.19 | AP21: =IFERROR(AG21+AI21+AJ21+AK21+AL21+AM21,"") -> 3.72 | AR21: =IFERROR(VLOOKUP($C21,[3]Real!$B$11:$Y$28,18,0),"") -> 3.72 | AS21: =IFERROR(IF(AR21-AP21=0,"",(AR21-AP21)),"") | BA21: 046E,062F
B22: W01 | C22: 002B2 | D22: 10.01 | E22: 46245 | G22: 46253 | I22: =+G22 -> 46253 | J22: =IF(I22>0,0,1) -> 0 | K22: 46268 | M22: =IF(AND(J22>0,L22>0),1,0) -> 0 | N22: =IF(AND(I22>0,K22>0),MAX(I22:K22)+1,"") -> 46269 | O22: =IF(N22>0,1,0) -> 1 | P22: =IF(O22>0,0,1) -> 0 | Q22: =IF(T22>0,"Selesai","Proses") -> Proses | R22: =IF(Q22="proses",1,0) -> 1 | S22: 46284 | V22: =AO22 -> 9.01 | W22: =AP22 -> 4.23 | X22: =IF(G22=0,"",D22-V22) -> 1 | Y22: =VLOOKUP($C22,[4]Nanas!$C$1336:$G$1416,5,0) -> PS | Z22: =1-X22/D22 -> 0.9000999 | AC22: Sudah | AF22: =IFERROR(VLOOKUP($C22,[3]Real!$B$11:$Y$28,20,0),"") -> 8.8 | AG22: =IFERROR(VLOOKUP($C22,[3]Real!$B$11:$Y$28,18,0),"") -> 4.02 | AH22: =SUMIFS('Input Real Tanam&Petik Nanas'!$J:$J,'Input Real Tanam&Petik Nanas'!$C:$C,$C22,'Input Real Tanam&Petik Nanas'!$B:$B,'Data Lokasi'!AH$13) -> 0 | AI22: =SUMIFS('Input Real Tanam&Petik Nanas'!$J:$J,'Input Real Tanam&Petik Nanas'!$C:$C,$C22,'Input Real Tanam&Petik Nanas'!$B:$B,'Data Lokasi'!AI$13) -> 0.21 | AJ22: =SUMIFS('Input Real Tanam&Petik Nanas'!$J:$J,'Input Real Tanam&Petik Nanas'!$C:$C,$C22,'Input Real Tanam&Petik Nanas'!$B:$B,'Data Lokasi'!AJ$13) -> 0 | AK22: =SUMIFS('Input Real Tanam&Petik Nanas'!$J:$J,'Input Real Tanam&Petik Nanas'!$C:$C,$C22,'Input Real Tanam&Petik Nanas'!$B:$B,'Data Lokasi'!AK$13) -> 0 | AL22: =SUMIFS('Input Real Tanam&Petik Nanas'!$J:$J,'Input Real Tanam&Petik Nanas'!$C:$C,$C22,'Input Real Tanam&Petik Nanas'!$B:$B,'Data Lokasi'!AL$13) -> 0 | AM22: =SUMIFS('Input Real Tanam&Petik Nanas'!$J:$J,'Input Real Tanam&Petik Nanas'!$C:$C,$C22,'Input Real Tanam&Petik Nanas'!$B:$B,'Data Lokasi'!AM$13) -> 0 | AO22: =IFERROR(AF22+AI22+AJ22+AK22+AL22+AM22,"") -> 9.01 | AP22: =IFERROR(AG22+AI22+AJ22+AK22+AL22+AM22,"") -> 4.23 | AR22: =IFERROR(VLOOKUP($C22,[3]Real!$B$11:$Y$28,18,0),"") -> 4.02 | AS22: =IFERROR(IF(AR22-AP22=0,"",(AR22-AP22)),"") -> -0.21 | BA22: 073B,075C,031B1,031B2
B23: W01 | C23: 020D | D23: 6.68 | E23: 46282 | G23: 46283 | I23: =+G23 -> 46283 | J23: =IF(I23>0,0,1) -> 0 | K23: 46301 | M23: =IF(AND(J23>0,L23>0),1,0) -> 0 | N23: =IF(AND(I23>0,K23>0),MAX(I23:K23)+1,"") -> 46302 | O23: =IF(N23>0,1,0) -> 1 | P23: =IF(O23>0,0,1) -> 0 | Q23: =IF(T23>0,"Selesai","Proses") -> Proses | R23: =IF(Q23="proses",1,0) -> 1 | S23: 46306 | V23: =AO23 -> 0.58 | W23: =AP23 -> 0.58 | X23: =IF(G23=0,"",D23-V23) -> 6.1 | Y23: RC | Z23: =1-X23/D23 -> 0.086826347 | AA23: =INDEX([5]Nanas!$M$1336:$M$1444,MATCH($C23,[5]Nanas!$C$1336:$C$1444,0)) -> 46248 | AB23: =$E$4-AA23 -> 60.615134 | AC23: Sudah | AF23: =IFERROR(VLOOKUP($C23,[3]Real!$B$11:$Y$28,20,0),"") -> 0.44 | AG23: =IFERROR(VLOOKUP($C23,[3]Real!$B$11:$Y$28,18,0),"") -> 0.44 | AH23: =SUMIFS('Input Real Tanam&Petik Nanas'!$J:$J,'Input Real Tanam&Petik Nanas'!$C:$C,$C23,'Input Real Tanam&Petik Nanas'!$B:$B,'Data Lokasi'!AH$13) -> 0.16 | AI23: =SUMIFS('Input Real Tanam&Petik Nanas'!$J:$J,'Input Real Tanam&Petik Nanas'!$C:$C,$C23,'Input Real Tanam&Petik Nanas'!$B:$B,'Data Lokasi'!AI$13) -> 0.14 | AJ23: =SUMIFS('Input Real Tanam&Petik Nanas'!$J:$J,'Input Real Tanam&Petik Nanas'!$C:$C,$C23,'Input Real Tanam&Petik Nanas'!$B:$B,'Data Lokasi'!AJ$13) -> 0 | AK23: =SUMIFS('Input Real Tanam&Petik Nanas'!$J:$J,'Input Real Tanam&Petik Nanas'!$C:$C,$C23,'Input Real Tanam&Petik Nanas'!$B:$B,'Data Lokasi'!AK$13) -> 0 | AL23: =SUMIFS('Input Real Tanam&Petik Nanas'!$J:$J,'Input Real Tanam&Petik Nanas'!$C:$C,$C23,'Input Real Tanam&Petik Nanas'!$B:$B,'Data Lokasi'!AL$13) -> 0 | AM23: =SUMIFS('Input Real Tanam&Petik Nanas'!$J:$J,'Input Real Tanam&Petik Nanas'!$C:$C,$C23,'Input Real Tanam&Petik Nanas'!$B:$B,'Data Lokasi'!AM$13) -> 0 | AO23: =IFERROR(AF23+AI23+AJ23+AK23+AL23+AM23,"") -> 0.58 | AP23: =IFERROR(AG23+AI23+AJ23+AK23+AL23+AM23,"") -> 0.58 | AR23: =IFERROR(VLOOKUP($C23,[3]Real!$B$11:$Y$28,18,0),"") -> 0.44 | AS23: =IFERROR(IF(AR23-AP23=0,"",(AR23-AP23)),"") -> -0.14 | BA23: 049A2,060A
B24: W02 | C24: 013C | D24: 8.09 | E24: 46193 | G24: 46213 | I24: =+G24 -> 46213 | J24: =IF(I24>0,0,1) -> 0 | K24: 46238 | M24: =IF(AND(J24>0,L24>0),1,0) -> 0 | N24: =IF(AND(I24>0,K24>0),MAX(I24:K24)+1,"") -> 46239 | O24: =IF(N24>0,1,0) -> 1 | P24: =IF(O24>0,0,1) -> 0 | Q24: =IF(T24>0,"Selesai","Proses") -> Proses | R24: =IF(Q24="proses",1,0) -> 1 | S24: 46301 | V24: =AO24 -> 7.78 | W24: =AP24 -> 7.78 | X24: =IF(G24=0,"",D24-V24) -> 0.31 | Y24: =VLOOKUP($C24,[4]Nanas!$C$1336:$G$1405,5,0) -> RC | Z24: =1-X24/D24 -> 0.96168109 | AA24: =INDEX([5]Nanas!$M$1336:$M$1444,MATCH($C24,[5]Nanas!$C$1336:$C$1444,0)) -> 46082 | AB24: =$E$4-AA24 -> 226.61513 | AC24: Sudah | AF24: =IFERROR(VLOOKUP($C24,[3]Real!$B$11:$Y$28,20,0),"") -> 7.54 | AG24: =IFERROR(VLOOKUP($C24,[3]Real!$B$11:$Y$28,18,0),"") -> 7.54 | AH24: =SUMIFS('Input Real Tanam&Petik Nanas'!$J:$J,'Input Real Tanam&Petik Nanas'!$C:$C,$C24,'Input Real Tanam&Petik Nanas'!$B:$B,'Data Lokasi'!AH$13) -> 0.22 | AI24: =SUMIFS('Input Real Tanam&Petik Nanas'!$J:$J,'Input Real Tanam&Petik Nanas'!$C:$C,$C24,'Input Real Tanam&Petik Nanas'!$B:$B,'Data Lokasi'!AI$13) -> 0.24 | AJ24: =SUMIFS('Input Real Tanam&Petik Nanas'!$J:$J,'Input Real Tanam&Petik Nanas'!$C:$C,$C24,'Input Real Tanam&Petik Nanas'!$B:$B,'Data Lokasi'!AJ$13) -> 0 | AK24: =SUMIFS('Input Real Tanam&Petik Nanas'!$J:$J,'Input Real Tanam&Petik Nanas'!$C:$C,$C24,'Input Real Tanam&Petik Nanas'!$B:$B,'Data Lokasi'!AK$13) -> 0 | AL24: =SUMIFS('Input Real Tanam&Petik Nanas'!$J:$J,'Input Real Tanam&Petik Nanas'!$C:$C,$C24,'Input Real Tanam&Petik Nanas'!$B:$B,'Data Lokasi'!AL$13) -> 0 | AM24: =SUMIFS('Input Real Tanam&Petik Nanas'!$J:$J,'Input Real Tanam&Petik Nanas'!$C:$C,$C24,'Input Real Tanam&Petik Nanas'!$B:$B,'Data Lokasi'!AM$13) -> 0 | AO24: =IFERROR(AF24+AI24+AJ24+AK24+AL24+AM24,"") -> 7.78 | AP24: =IFERROR(AG24+AI24+AJ24+AK24+AL24+AM24,"") -> 7.78 | AR24: =IFERROR(VLOOKUP($C24,[3]Real!$B$11:$Y$28,18,0),"") -> 7.54 | AS24: =IFERROR(IF(AR24-AP24=0,"",(AR24-AP24)),"") -> -0.24 | BA24: 004C3,020E,027H,027I
B25: W02 | C25: 013F | D25: 7.64 | E25: 46193 | G25: 46213 | I25: =+G25 -> 46213 | J25: =IF(I25>0,0,1) -> 0 | K25: 46238 | M25: =IF(AND(J25>0,L25>0),1,0) -> 0 | N25: =IF(AND(I25>0,K25>0),MAX(I25:K25)+1,"") -> 46239 | O25: =IF(N25>0,1,0) -> 1 | P25: =IF(O25>0,0,1) -> 0 | Q25: =IF(T25>0,"Selesai","Proses") -> Proses | R25: =IF(Q25="proses",1,0) -> 1 | S25: 46302 | V25: =AO25 -> 7.03 | W25: =AP25 -> 7.03 | X25: =IF(G25=0,"",D25-V25) -> 0.61 | Y25: =VLOOKUP($C25,[4]Nanas!$C$1336:$G$1405,5,0) -> RC | Z25: =1-X25/D25 -> 0.92015707 | AA25: =INDEX([5]Nanas!$M$1336:$M$1444,MATCH($C25,[5]Nanas!$C$1336:$C$1444,0)) -> 46012 | AB25: =$E$4-AA25 -> 296.61513 | AC25: Sudah | AF25: =IFERROR(VLOOKUP($C25,[3]Real!$B$11:$Y$28,20,0),"") -> 5.38 | AG25: =IFERROR(VLOOKUP($C25,[3]Real!$B$11:$Y$28,18,0),"") -> 5.38 | AH25: =SUMIFS('Input Real Tanam&Petik Nanas'!$J:$J,'Input Real Tanam&Petik Nanas'!$C:$C,$C25,'Input Real Tanam&Petik Nanas'!$B:$B,'Data Lokasi'!AH$13) -> 1.47 | AI25: =SUMIFS('Input Real Tanam&Petik Nanas'!$J:$J,'Input Real Tanam&Petik Nanas'!$C:$C,$C25,'Input Real Tanam&Petik Nanas'!$B:$B,'Data Lokasi'!AI$13) -> 1.65 | AJ25: =SUMIFS('Input Real Tanam&Petik Nanas'!$J:$J,'Input Real Tanam&Petik Nanas'!$C:$C,$C25,'Input Real Tanam&Petik Nanas'!$B:$B,'Data Lokasi'!AJ$13) -> 0 | AK25: =SUMIFS('Input Real Tanam&Petik Nanas'!$J:$J,'Input Real Tanam&Petik Nanas'!$C:$C,$C25,'Input Real Tanam&Petik Nanas'!$B:$B,'Data Lokasi'!AK$13) -> 0 | AL25: =SUMIFS('Input Real Tanam&Petik Nanas'!$J:$J,'Input Real Tanam&Petik Nanas'!$C:$C,$C25,'Input Real Tanam&Petik Nanas'!$B:$B,'Data Lokasi'!AL$13) -> 0 | AM25: =SUMIFS('Input Real Tanam&Petik Nanas'!$J:$J,'Input Real Tanam&Petik Nanas'!$C:$C,$C25,'Input Real Tanam&Petik Nanas'!$B:$B,'Data Lokasi'!AM$13) -> 0 | AO25: =IFERROR(AF25+AI25+AJ25+AK25+AL25+AM25,"") -> 7.03 | AP25: =IFERROR(AG25+AI25+AJ25+AK25+AL25+AM25,"") -> 7.03 | AR25: =IFERROR(VLOOKUP($C25,[3]Real!$B$11:$Y$28,18,0),"") -> 5.38 | AS25: =IFERROR(IF(AR25-AP25=0,"",(AR25-AP25)),"") -> -1.65 | BA25: 020E
B26: W03 | C26: 063A | D26: 10.65 | E26: 46278 | G26: 46279 | I26: =+G26 -> 46279 | J26: =IF(I26>0,0,1) -> 0 | K26: 46289 | M26: =IF(AND(J26>0,L26>0),1,0) -> 0 | N26: =IF(AND(I26>0,K26>0),MAX(I26:K26)+1,"") -> 46290 | O26: =IF(N26>0,1,0) -> 1 | P26: =IF(O26>0,0,1) -> 0 | Q26: =IF(T26>0,"Selesai","Proses") -> Proses | R26: =IF(Q26="proses",1,0) -> 1 | S26: 46292 | V26: =AO26 -> 10.52 | W26: =AP26 -> 5.47 | X26: =IF(G26=0,"",D26-V26) -> 0.13 | Y26: BB | Z26: =1-X26/D26 -> 0.98779343 | AC26: Sudah | AF26: =IFERROR(VLOOKUP($C26,[3]Real!$B$11:$Y$28,20,0),"") -> 10.44 | AG26: =IFERROR(VLOOKUP($C26,[3]Real!$B$11:$Y$28,18,0),"") -> 5.39 | AH26: =SUMIFS('Input Real Tanam&Petik Nanas'!$J:$J,'Input Real Tanam&Petik Nanas'!$C:$C,$C26,'Input Real Tanam&Petik Nanas'!$B:$B,'Data Lokasi'!AH$13) -> 0 | AI26: =SUMIFS('Input Real Tanam&Petik Nanas'!$J:$J,'Input Real Tanam&Petik Nanas'!$C:$C,$C26,'Input Real Tanam&Petik Nanas'!$B:$B,'Data Lokasi'!AI$13) -> 0.08 | AJ26: =SUMIFS('Input Real Tanam&Petik Nanas'!$J:$J,'Input Real Tanam&Petik Nanas'!$C:$C,$C26,'Input Real Tanam&Petik Nanas'!$B:$B,'Data Lokasi'!AJ$13) -> 0 | AK26: =SUMIFS('Input Real Tanam&Petik Nanas'!$J:$J,'Input Real Tanam&Petik Nanas'!$C:$C,$C26,'Input Real Tanam&Petik Nanas'!$B:$B,'Data Lokasi'!AK$13) -> 0 | AL26: =SUMIFS('Input Real Tanam&Petik Nanas'!$J:$J,'Input Real Tanam&Petik Nanas'!$C:$C,$C26,'Input Real Tanam&Petik Nanas'!$B:$B,'Data Lokasi'!AL$13) -> 0 | AM26: =SUMIFS('Input Real Tanam&Petik Nanas'!$J:$J,'Input Real Tanam&Petik Nanas'!$C:$C,$C26,'Input Real Tanam&Petik Nanas'!$B:$B,'Data Lokasi'!AM$13) -> 0 | AO26: =IFERROR(AF26+AI26+AJ26+AK26+AL26+AM26,"") -> 10.52 | AP26: =IFERROR(AG26+AI26+AJ26+AK26+AL26+AM26,"") -> 5.47 | AR26: =IFERROR(VLOOKUP($C26,[3]Real!$B$11:$Y$28,18,0),"") -> 5.39 | AS26: =IFERROR(IF(AR26-AP26=0,"",(AR26-AP26)),"") -> -0.08 | BA26: 052A,062F1,062M
B27: W04 | C27: 050A1 | D27: 7.19 | E27: 46281 | G27: 46282 | I27: =+G27 -> 46282 | J27: =IF(I27>0,0,1) -> 0 | K27: 46289 | M27: =IF(AND(J27>0,L27>0),1,0) -> 0 | N27: =IF(AND(I27>0,K27>0),MAX(I27:K27)+1,"") -> 46290 | O27: =IF(N27>0,1,0) -> 1 | P27: =IF(O27>0,0,1) -> 0 | Q27: =IF(T27>0,"Selesai","Proses") -> Proses | R27: =IF(Q27="proses",1,0) -> 1 | S27: 46290 | V27: =AO27 -> 6.82 | W27: =AP27 -> 2.93 | X27: =IF(G27=0,"",D27-V27) -> 0.37 | Y27: PS | Z27: =1-X27/D27 -> 0.94853964 | AC27: Sudah | AF27: =IFERROR(VLOOKUP($C27,[3]Real!$B$11:$Y$28,20,0),"") -> 6.82 | AG27: =IFERROR(VLOOKUP($C27,[3]Real!$B$11:$Y$28,18,0),"") -> 2.93 | AH27: =SUMIFS('Input Real Tanam&Petik Nanas'!$J:$J,'Input Real Tanam&Petik Nanas'!$C:$C,$C27,'Input Real Tanam&Petik Nanas'!$B:$B,'Data Lokasi'!AH$13) -> 0 | AI27: =SUMIFS('Input Real Tanam&Petik Nanas'!$J:$J,'Input Real Tanam&Petik Nanas'!$C:$C,$C27,'Input Real Tanam&Petik Nanas'!$B:$B,'Data Lokasi'!AI$13) -> 0 | AJ27: =SUMIFS('Input Real Tanam&Petik Nanas'!$J:$J,'Input Real Tanam&Petik Nanas'!$C:$C,$C27,'Input Real Tanam&Petik Nanas'!$B:$B,'Data Lokasi'!AJ$13) -> 0 | AK27: =SUMIFS('Input Real Tanam&Petik Nanas'!$J:$J,'Input Real Tanam&Petik Nanas'!$C:$C,$C27,'Input Real Tanam&Petik Nanas'!$B:$B,'Data Lokasi'!AK$13) -> 0 | AL27: =SUMIFS('Input Real Tanam&Petik Nanas'!$J:$J,'Input Real Tanam&Petik Nanas'!$C:$C,$C27,'Input Real Tanam&Petik Nanas'!$B:$B,'Data Lokasi'!AL$13) -> 0 | AM27: =SUMIFS('Input Real Tanam&Petik Nanas'!$J:$J,'Input Real Tanam&Petik Nanas'!$C:$C,$C27,'Input Real Tanam&Petik Nanas'!$B:$B,'Data Lokasi'!AM$13) -> 0 | AO27: =IFERROR(AF27+AI27+AJ27+AK27+AL27+AM27,"") -> 6.82 | AP27: =IFERROR(AG27+AI27+AJ27+AK27+AL27+AM27,"") -> 2.93 | AR27: =IFERROR(VLOOKUP($C27,[3]Real!$B$11:$Y$28,18,0),"") -> 2.93 | AS27: =IFERROR(IF(AR27-AP27=0,"",(AR27-AP27)),"") | BA27: 075C,074C
B28: W06 | C28: 077A | D28: 9.22 | E28: 46267 | G28: 46268 | I28: =+G28 -> 46268 | J28: =IF(I28>0,0,1) -> 0 | K28: 46303 | M28: =IF(AND(J28>0,L28>0),1,0) -> 0 | N28: =IF(AND(I28>0,K28>0),MAX(I28:K28)+1,"") -> 46304 | O28: =IF(N28>0,1,0) -> 1 | P28: =IF(O28>0,0,1) -> 0 | Q28: =IF(T28>0,"Selesai","Proses") -> Proses | R28: =IF(Q28="proses",1,0) -> 1 | S28: 46304 | V28: =AO28 -> 5.34 | W28: =AP28 -> 5.34 | X28: =IF(G28=0,"",D28-V28) -> 3.88 | Y28: =INDEX([6]Nanas!$G$1429:$G$1436,MATCH($C28,[6]Nanas!$C$1429:$C$1436,0)) -> RC | Z28: =1-X28/D28 -> 0.5791757 | AA28: =INDEX([5]Nanas!$M$1336:$M$1444,MATCH($C28,[5]Nanas!$C$1336:$C$1444,0)) -> 46237 | AB28: =$E$4-AA28 -> 71.615134 | AC28: Sudah | AF28: =IFERROR(VLOOKUP($C28,[3]Real!$B$11:$Y$28,20,0),"") -> 4.39 | AG28: =IFERROR(VLOOKUP($C28,[3]Real!$B$11:$Y$28,18,0),"") -> 4.39 | AH28: =SUMIFS('Input Real Tanam&Petik Nanas'!$J:$J,'Input Real Tanam&Petik Nanas'!$C:$C,$C28,'Input Real Tanam&Petik Nanas'!$B:$B,'Data Lokasi'!AH$13) -> 0.56 | AI28: =SUMIFS('Input Real Tanam&Petik Nanas'!$J:$J,'Input Real Tanam&Petik Nanas'!$C:$C,$C28,'Input Real Tanam&Petik Nanas'!$B:$B,'Data Lokasi'!AI$13) -> 0.95 | AJ28: =SUMIFS('Input Real Tanam&Petik Nanas'!$J:$J,'Input Real Tanam&Petik Nanas'!$C:$C,$C28,'Input Real Tanam&Petik Nanas'!$B:$B,'Data Lokasi'!AJ$13) -> 0 | AK28: =SUMIFS('Input Real Tanam&Petik Nanas'!$J:$J,'Input Real Tanam&Petik Nanas'!$C:$C,$C28,'Input Real Tanam&Petik Nanas'!$B:$B,'Data Lokasi'!AK$13) -> 0 | AL28: =SUMIFS('Input Real Tanam&Petik Nanas'!$J:$J,'Input Real Tanam&Petik Nanas'!$C:$C,$C28,'Input Real Tanam&Petik Nanas'!$B:$B,'Data Lokasi'!AL$13) -> 0 | AM28: =SUMIFS('Input Real Tanam&Petik Nanas'!$J:$J,'Input Real Tanam&Petik Nanas'!$C:$C,$C28,'Input Real Tanam&Petik Nanas'!$B:$B,'Data Lokasi'!AM$13) -> 0 | AO28: =IFERROR(AF28+AI28+AJ28+AK28+AL28+AM28,"") -> 5.34 | AP28: =IFERROR(AG28+AI28+AJ28+AK28+AL28+AM28,"") -> 5.34 | AR28: =IFERROR(VLOOKUP($C28,[3]Real!$B$11:$Y$28,18,0),"") -> 4.39 | AS28: =IFERROR(IF(AR28-AP28=0,"",(AR28-AP28)),"") -> -0.95 | BA28: 071B,072L,096J2,091C
B29: W06 | C29: 078E2 | D29: 12.75 | E29: 46242 | G29: 46244 | I29: =+G29 -> 46244 | J29: =IF(I29>0,0,1) -> 0 | K29: 46268 | M29: =IF(AND(J29>0,L29>0),1,0) -> 0 | N29: =IF(AND(I29>0,K29>0),MAX(I29:K29)+1,"") -> 46269 | O29: =IF(N29>0,1,0) -> 1 | P29: =IF(O29>0,0,1) -> 0 | Q29: =IF(T29>0,"Selesai","Proses") -> Proses | R29: =IF(Q29="proses",1,0) -> 1 | S29: 46290 | V29: =AO29 -> 9.51 | W29: =AP29 -> 7.12 | X29: =IF(G29=0,"",D29-V29) -> 3.24 | Y29: =VLOOKUP($C29,[4]Nanas!$C$1336:$G$1416,5,0) -> RC | Z29: =1-X29/D29 -> 0.74588235 | AC29: Sudah | AF29: =IFERROR(VLOOKUP($C29,[3]Real!$B$11:$Y$28,20,0),"") -> 9.08 | AG29: =IFERROR(VLOOKUP($C29,[3]Real!$B$11:$Y$28,18,0),"") -> 6.69 | AH29: =SUMIFS('Input Real Tanam&Petik Nanas'!$J:$J,'Input Real Tanam&Petik Nanas'!$C:$C,$C29,'Input Real Tanam&Petik Nanas'!$B:$B,'Data Lokasi'!AH$13) -> 0.08 | AI29: =SUMIFS('Input Real Tanam&Petik Nanas'!$J:$J,'Input Real Tanam&Petik Nanas'!$C:$C,$C29,'Input Real Tanam&Petik Nanas'!$B:$B,'Data Lokasi'!AI$13) -> 0.43 | AJ29: =SUMIFS('Input Real Tanam&Petik Nanas'!$J:$J,'Input Real Tanam&Petik Nanas'!$C:$C,$C29,'Input Real Tanam&Petik Nanas'!$B:$B,'Data Lokasi'!AJ$13) -> 0 | AK29: =SUMIFS('Input Real Tanam&Petik Nanas'!$J:$J,'Input Real Tanam&Petik Nanas'!$C:$C,$C29,'Input Real Tanam&Petik Nanas'!$B:$B,'Data Lokasi'!AK$13) -> 0 | AL29: =SUMIFS('Input Real Tanam&Petik Nanas'!$J:$J,'Input Real Tanam&Petik Nanas'!$C:$C,$C29,'Input Real Tanam&Petik Nanas'!$B:$B,'Data Lokasi'!AL$13) -> 0 | AM29: =SUMIFS('Input Real Tanam&Petik Nanas'!$J:$J,'Input Real Tanam&Petik Nanas'!$C:$C,$C29,'Input Real Tanam&Petik Nanas'!$B:$B,'Data Lokasi'!AM$13) -> 0 | AO29: =IFERROR(AF29+AI29+AJ29+AK29+AL29+AM29,"") -> 9.51 | AP29: =IFERROR(AG29+AI29+AJ29+AK29+AL29+AM29,"") -> 7.12 | AR29: =IFERROR(VLOOKUP($C29,[3]Real!$B$11:$Y$28,18,0),"") -> 6.69 | AS29: =IFERROR(IF(AR29-AP29=0,"",(AR29-AP29)),"") -> -0.43 | BA29: 016B,077C,052B
F30: =IF(E30>0,1,0) -> 0 | H30: =IF(G30>0,1,0) -> 0 | J30: =IF(I30>0,0,1) -> 1 | L30: =IF(K30>0,0,1) -> 1 | M30: =IF(AND(J30>0,L30>0),1,0) -> 1 | N30: =IF(AND(I30>0,K30>0),MAX(I30:K30)+1,"") | O30: =IF(N30>0,1,0) -> 1 | P30: =IF(O30>0,0,1) -> 0 | R30: =IF(Q30="proses",1,0) -> 0 | U30: =IF(T30>0,1,0) -> 0 | X30: =IF(G30=0,"",D30-V30) | AF30: =SUM(AF15:AF29) -> 93.22 | AG30: =SUM(AG15:AG29) -> 47.45 | AH30: =SUM(AH15:AH29) -> 3.13 | AI30: =SUM(AI15:AI29) -> 3.7 | AJ30: =SUM(AJ15:AJ29) -> 0 | AK30: =SUM(AK15:AK29) -> 0 | AL30: =SUM(AL15:AL29) -> 0 | AM30: =SUM(AM15:AM29) -> 0 | ... AP30: =SUM(AP15:AP29) -> 51.15 | AR30: =SUM(AR15:AR29) -> 47.45 | AS30: =SUM(AS15:AS29) -> -3.7 | AU30: =SUM(AU1276:AU1278) -> 0 | AV30: =SUM(AV1276:AV1278) -> 0 | AX30: =SUM(AX1276:AX1278) -> 0 | AY30: =SUM(AY1276:AY1278) -> 0
B31: Lokasi SN sudah pree | O31: =IF(N31>0,1,0) -> 0 | AF31: SN+Pree
AF32: =SUM(X33:X34) -> 13.35
B33: W02 | C33: 013E | D33: 7.09 | E33: 46234 | G33: 46252 | J33: =IF(I33>0,0,1) -> 1 | K33: 46293 | M33: =IF(AND(J33>0,L33>0),1,0) -> 0 | O33: =IF(N33>0,1,0) -> 0 | P33: =IF(O33>0,0,1) -> 1 | R33: =IF(Q33="proses",1,0) -> 0 | X33: =IF(G33=0,"",D33-V33) -> 7.09 | Y33: =VLOOKUP($C33,[4]Nanas!$C$1336:$G$1416,5,0) -> PY | Z33: =1-X33/D33 -> 0 | AC33: Sudah
B34: W07 | C34: 085D | D34: 6.26 | E34: 46265 | G34: 46267 | J34: =IF(I34>0,0,1) -> 1 | K34: 46296 | M34: =IF(AND(J34>0,L34>0),1,0) -> 0 | O34: =IF(N34>0,1,0) -> 0 | P34: =IF(O34>0,0,1) -> 1 | R34: =IF(Q34="proses",1,0) -> 0 | X34: =IF(G34=0,"",D34-V34) -> 6.26 | Y34: RC | Z34: =1-X34/D34 -> 0 | AA34: =INDEX([5]Nanas!$M$1336:$M$1444,MATCH($C34,[5]Nanas!$C$1336:$C$1444,0)) -> 46239 | AB34: =$E$4-AA34 -> 69.615134
B35: Lokasi SN blum pree & Examini | O35: =IF(N35>0,1,0) -> 0 | AF35: SN
AF36: =SUM(X37:X63) -> 199.55
B37: W06 | C37: 092C1 | D37: 9.23 | E37: 46212 | G37: 46213 | J37: =IF(I37>0,0,1) -> 1 | M37: =IF(AND(J37>0,L37>0),1,0) -> 0 | O37: =IF(N37>0,1,0) -> 0 | P37: =IF(O37>0,0,1) -> 1 | R37: =IF(Q37="proses",1,0) -> 0 | X37: =IF(G37=0,"",D37-V37) -> 9.23 | Y37: =VLOOKUP($C37,[4]Nanas!$C$1336:$G$1416,5,0) -> RC | Z37: =1-X37/D37 -> 0 | AA37: =INDEX([5]Nanas!$M$1336:$M$1444,MATCH($C37,[5]Nanas!$C$1336:$C$1444,0)) -> 46053 | AB37: =$E$4-AA37 -> 255.61513
B38: W06 | C38: 092E1 | D38: 8.71 | E38: 46214 | G38: 46252 | J38: =IF(I38>0,0,1) -> 1 | M38: =IF(AND(J38>0,L38>0),1,0) -> 0 | O38: =IF(N38>0,1,0) -> 0 | P38: =IF(O38>0,0,1) -> 1 | R38: =IF(Q38="proses",1,0) -> 0 | X38: =IF(G38=0,"",D38-V38) -> 8.71 | Y38: =VLOOKUP($C38,[4]Nanas!$C$1336:$G$1416,5,0) -> BB | Z38: =1-X38/D38 -> 0 | AA38: =INDEX([5]Nanas!$M$1336:$M$1444,MATCH($C38,[5]Nanas!$C$1336:$C$1444,0)) -> 46008 | AB38: =$E$4-AA38 -> 300.61513 | AC38: Sudah
B39: W06 | C39: 093D | D39: 11.63 | E39: 46249 | G39: 46253 | J39: =IF(I39>0,0,1) -> 1 | M39: =IF(AND(J39>0,L39>0),1,0) -> 0 | O39: =IF(N39>0,1,0) -> 0 | P39: =IF(O39>0,0,1) -> 1 | R39: =IF(Q39="proses",1,0) -> 0 | X39: =IF(G39=0,"",D39-V39) -> 11.63 | Y39: =VLOOKUP($C39,[4]Nanas!$C$1336:$G$1416,5,0) -> RC | Z39: =1-X39/D39 -> 0 | AA39: =INDEX([5]Nanas!$M$1336:$M$1444,MATCH($C39,[5]Nanas!$C$1336:$C$1444,0)) -> 46147 | AB39: =$E$4-AA39 -> 161.61513 | AC39: Sudah
B40: W05 | C40: 070D | D40: 6.05 | E40: 46252 | G40: 46253 | J40: =IF(I40>0,0,1) -> 1 | M40: =IF(AND(J40>0,L40>0),1,0) -> 0 | O40: =IF(N40>0,1,0) -> 0 | P40: =IF(O40>0,0,1) -> 1 | R40: =IF(Q40="proses",1,0) -> 0 | X40: =IF(G40=0,"",D40-V40) -> 6.05 | Y40: =VLOOKUP($C40,[2]Nanas!$C$1336:$G$1416,5,0) -> RC | Z40: =1-X40/D40 -> 0 | AA40: =INDEX([5]Nanas!$M$1336:$M$1444,MATCH($C40,[5]Nanas!$C$1336:$C$1444,0)) -> 46206 | AB40: =$E$4-AA40 -> 102.61513 | AC40: Sudah
B41: W06 | C41: 075E | D41: 7.56 | E41: 46263 | G41: 46267 | J41: =IF(I41>0,0,1) -> 1 | M41: =IF(AND(J41>0,L41>0),1,0) -> 0 | O41: =IF(N41>0,1,0) -> 0 | P41: =IF(O41>0,0,1) -> 1 | R41: =IF(Q41="proses",1,0) -> 0 | X41: =IF(G41=0,"",D41-V41) -> 7.56 | Y41: BB | Z41: =1-X41/D41 -> 0 | AA41: =INDEX([5]Nanas!$M$1336:$M$1444,MATCH($C41,[5]Nanas!$C$1336:$C$1444,0)) -> 46237 | AB41: =$E$4-AA41 -> 71.615134
B42: W03 | C42: 047K1 | D42: 5.21 | E42: 46266 | G42: 46270 | J42: =IF(I42>0,0,1) -> 1 | M42: =IF(AND(J42>0,L42>0),1,0) -> 0 | O42: =IF(N42>0,1,0) -> 0 | P42: =IF(O42>0,0,1) -> 1 | R42: =IF(Q42="proses",1,0) -> 0 | X42: =IF(G42=0,"",D42-V42) -> 5.21 | Y42: RC | Z42: =1-X42/D42 -> 0 | AA42: =INDEX([5]Nanas!$M$1336:$M$1444,MATCH($C42,[5]Nanas!$C$1336:$C$1444,0)) -> 46238 | AB42: =$E$4-AA42 -> 70.615134
B43: W05 | C43: 070E4 | D43: 6.91 | E43: 46287 | G43: 46288 | J43: =IF(I43>0,0,1) -> 1 | M43: =IF(AND(J43>0,L43>0),1,0) -> 0 | O43: =IF(N43>0,1,0) -> 0 | P43: =IF(O43>0,0,1) -> 1 | R43: =IF(Q43="proses",1,0) -> 0 | X43: =IF(G43=0,"",D43-V43) -> 6.91 | Y43: PS | Z43: =1-X43/D43 -> 0 | AA43: 46241 | AB43: =$E$4-AA43 -> 67.615134 | AC43: Sudah
B44: W04 | C44: 050A2 | D44: 5.27 | E44: 46281 | G44: 46290 | J44: =IF(I44>0,0,1) -> 1 | M44: =IF(AND(J44>0,L44>0),1,0) -> 0 | O44: =IF(N44>0,1,0) -> 0 | P44: =IF(O44>0,0,1) -> 1 | R44: =IF(Q44="proses",1,0) -> 0 | X44: =IF(G44=0,"",D44-V44) -> 5.27 | Y44: PS | Z44: =1-X44/D44 -> 0 | AC44: Sudah
...

Sheet Prioritas
B2: Monitor Siap Nanas PG1
B4: Wil. | C4: Lokasi | D4: Netto | E4: Jln & Saluran | F4: Pree | G4: Examini | H4: Siap Drop | I4: Jenis Bibit | J4: Kelas Bibit | K4: Tgl Mulai Tanam | L4: Luas Sudah Tanam | M4: Sisa Blm Tanam | N4: Percent Excamini | O4: Prioritas Excamini | P4: Keterangan
B5: Proses Tanam | R5: =+R6/4 -> 5
B6: W01 | C6: 003J | D6: 4.9 | E6: 44335 | F6: =VLOOKUP(C6,'Data Lokasi'!$C$203:$S$1681,9,0) -> 44338 | G6: =VLOOKUP(C6,'Data Lokasi'!$C$203:$S$1681,7,0) -> 44352 | H6: =MAX(F6:G6)+1 -> 44353 | I6: =VLOOKUP(C6,[15]Sheet1!$B$40:$F$71,4,0) -> Nursery | J6: Kecil | K6: =VLOOKUP(C6,'Data Lokasi'!$C$203:$S$1681,17,0) -> 44343 | L6: =VLOOKUP(C6,'Data Lokasi'!$C$203:$X$1681,21,0) -> 0 | M6: =VLOOKUP(C6,'Data Lokasi'!$C$203:$X$1681,22,0) -> 0 | R6: 20
B7: W01 | C7: 010B | D7: =VLOOKUP(C7,'Data Lokasi'!$C$203:$D$1681,2,0) -> 3.34 | E7: =VLOOKUP(C7,'Data Lokasi'!$C$203:$S$1681,5,0) -> 44335 | F7: =VLOOKUP(C7,'Data Lokasi'!$C$203:$S$1681,9,0) -> 44338 | G7: =VLOOKUP(C7,'Data Lokasi'!$C$203:$S$1681,7,0) -> 44357 | H7: =MAX(F7:G7)+1 -> 44358 | I7: =VLOOKUP(C7,[15]Sheet1!$B$40:$F$71,4,0) -> Crown | J7: =VLOOKUP(C7,[15]Sheet1!$B$40:$F$71,5,0) -> Kecil | K7: =VLOOKUP(C7,'Data Lokasi'!$C$203:$S$1681,17,0) -> 44347 | L7: =VLOOKUP(C7,'Data Lokasi'!$C$203:$X$1681,21,0) -> 0 | M7: =VLOOKUP(C7,'Data Lokasi'!$C$203:$X$1681,22,0) -> 0
B8: W01 | C8: 012B | D8: 10.3 | E8: =VLOOKUP(C8,'Data Lokasi'!$C$203:$S$1681,5,0) -> 44310 | F8: =VLOOKUP(C8,'Data Lokasi'!$C$203:$S$1681,9,0) -> 44317 | G8: =VLOOKUP(C8,'Data Lokasi'!$C$203:$S$1681,7,0) -> 44357 | H8: =MAX(F8:G8)+1 -> 44358 | I8: Sucker | J8: =VLOOKUP(C8,[15]Sheet1!$B$40:$F$71,5,0) -> Besar | K8: =VLOOKUP(C8,'Data Lokasi'!$C$203:$S$1681,17,0) -> 44347 | L8: =VLOOKUP(C8,'Data Lokasi'!$C$203:$X$1681,21,0) -> 0 | M8: 0
B9: W03 | C9: 050A | D9: =VLOOKUP(C9,'Data Lokasi'!$C$203:$D$1681,2,0) -> 12.16 | E9: =VLOOKUP(C9,'Data Lokasi'!$C$203:$S$1681,5,0) -> 44307 | F9: =VLOOKUP(C9,'Data Lokasi'!$C$203:$S$1681,9,0) -> 44308 | G9: =VLOOKUP(C9,'Data Lokasi'!$C$203:$S$1681,7,0) -> 44337 | H9: =MAX(F9:G9)+1 -> 44338 | I9: =VLOOKUP(C9,[15]Sheet1!$B$40:$F$71,4,0) -> Sucker | J9: =VLOOKUP(C9,[15]Sheet1!$B$40:$F$71,5,0) -> Sedang | K9: =VLOOKUP(C9,'Data Lokasi'!$C$203:$S$1681,17,0) -> 44347 | L9: 0 | M9: =VLOOKUP(C9,'Data Lokasi'!$C$203:$X$1681,22,0) -> 0
B10: W02 | C10: 062A1 | D10: =VLOOKUP(C10,'Data Lokasi'!$C$203:$D$1681,2,0) -> 5.7 | E10: =VLOOKUP(C10,'Data Lokasi'!$C$203:$S$1681,5,0) -> 44305 | F10: =VLOOKUP(C10,'Data Lokasi'!$C$203:$S$1681,9,0) -> 44309 | G10: =VLOOKUP(C10,'Data Lokasi'!$C$203:$S$1681,7,0) -> 44356 | H10: =MAX(F10:G10)+1 -> 44357 | I10: =VLOOKUP(C10,[15]Sheet1!$B$40:$F$71,4,0) -> Sucker | J10: =VLOOKUP(C10,[15]Sheet1!$B$40:$F$71,5,0) -> Besar | K10: =VLOOKUP(C10,'Data Lokasi'!$C$203:$S$1681,17,0) -> 44362 | L10: =VLOOKUP(C10,'Data Lokasi'!$C$203:$X$1681,21,0) -> 0 | M10: =VLOOKUP(C10,'Data Lokasi'!$C$203:$X$1681,22,0) -> 0
B11: W03 | C11: 066G | D11: =VLOOKUP(C11,'Data Lokasi'!$C$203:$D$1681,2,0) -> 13.48 | E11: =VLOOKUP(C11,'Data Lokasi'!$C$203:$S$1681,5,0) -> 44312 | F11: =VLOOKUP(C11,'Data Lokasi'!$C$203:$S$1681,9,0) -> 44322 | G11: =VLOOKUP(C11,'Data Lokasi'!$C$203:$S$1681,7,0) -> 44352 | H11: =MAX(F11:G11)+1 -> 44353 | I11: =VLOOKUP(C11,[15]Sheet1!$B$40:$F$71,4,0) -> Crown | J11: =VLOOKUP(C11,[15]Sheet1!$B$40:$F$71,5,0) -> Kecil | K11: =VLOOKUP(C11,'Data Lokasi'!$C$203:$S$1681,17,0) -> 44337 | L11: =VLOOKUP(C11,'Data Lokasi'!$C$203:$X$1681,21,0) -> 0 | M11: 0 | N11: 0.95
B12: W03 | C12: 066Q2 | D12: =VLOOKUP(C12,'Data Lokasi'!$C$203:$D$1681,2,0) -> 8.13 | E12: =VLOOKUP(C12,'Data Lokasi'!$C$203:$S$1681,5,0) -> 44345 | F12: =VLOOKUP(C12,'Data Lokasi'!$C$203:$S$1681,9,0) -> 44355 | G12: =VLOOKUP(C12,'Data Lokasi'!$C$203:$S$1681,7,0) -> 44363 | H12: =MAX(F12:G12)+1 -> 44364 | I12: =VLOOKUP(C12,[15]Sheet1!$B$40:$F$71,4,0) -> Nursery | J12: =VLOOKUP(C12,[15]Sheet1!$B$40:$F$71,5,0) -> Sedang | K12: =VLOOKUP(C12,'Data Lokasi'!$C$203:$S$1681,17,0) -> 44358 | L12: =VLOOKUP(C12,'Data Lokasi'!$C$203:$X$1681,21,0) -> 0 | M12: =VLOOKUP(C12,'Data Lokasi'!$C$203:$X$1681,22,0) -> 0
B13: W03 | C13: 066T | D13: =VLOOKUP(C13,'Data Lokasi'!$C$203:$D$1681,2,0) -> 7.7 | E13: =VLOOKUP(C13,'Data Lokasi'!$C$203:$S$1681,5,0) -> 44340 | F13: =VLOOKUP(C13,'Data Lokasi'!$C$203:$S$1681,9,0) -> 44355 | G13: =VLOOKUP(C13,'Data Lokasi'!$C$203:$S$1681,7,0) -> 44367 | H13: =MAX(F13:G13)+1 -> 44368 | I13: =VLOOKUP(C13,[15]Sheet1!$B$40:$F$71,4,0) -> Nursery | J13: =VLOOKUP(C13,[15]Sheet1!$B$40:$F$71,5,0) -> Sedang | K13: =VLOOKUP(C13,'Data Lokasi'!$C$203:$S$1681,17,0) -> 44358 | L13: =VLOOKUP(C13,'Data Lokasi'!$C$203:$X$1681,21,0) -> 0 | M13: =VLOOKUP(C13,'Data Lokasi'!$C$203:$X$1681,22,0) -> 0 | N13: 0.05
B14: W03 | C14: 067E | D14: =VLOOKUP(C14,'Data Lokasi'!$C$203:$D$1681,2,0) -> 8.39 | E14: =VLOOKUP(C14,'Data Lokasi'!$C$203:$S$1681,5,0) -> 44315 | F14: =VLOOKUP(C14,'Data Lokasi'!$C$203:$S$1681,9,0) -> 44333 | G14: =VLOOKUP(C14,'Data Lokasi'!$C$203:$S$1681,7,0) -> 44348 | H14: =MAX(F14:G14)+1 -> 44349 | I14: =VLOOKUP(C14,[15]Sheet1!$B$40:$F$71,4,0) -> Crown | J14: =VLOOKUP(C14,[15]Sheet1!$B$40:$F$71,5,0) -> Kecil | K14: =VLOOKUP(C14,'Data Lokasi'!$C$203:$S$1681,17,0) -> 44341 | L14: =VLOOKUP(C14,'Data Lokasi'!$C$203:$X$1681,21,0) -> 0 | M14: =VLOOKUP(C14,'Data Lokasi'!$C$203:$X$1681,22,0) -> 0
B15: W03 | C15: 067G | D15: =VLOOKUP(C15,'Data Lokasi'!$C$203:$D$1681,2,0) -> 1.92 | E15: =VLOOKUP(C15,'Data Lokasi'!$C$203:$S$1681,5,0) -> 44315 | F15: =VLOOKUP(C15,'Data Lokasi'!$C$203:$S$1681,9,0) -> 44333 | G15: =VLOOKUP(C15,'Data Lokasi'!$C$203:$S$1681,7,0) -> 44348 | H15: =MAX(F15:G15)+1 -> 44349 | I15: =VLOOKUP(C15,[15]Sheet1!$B$40:$F$71,4,0) -> Crown | J15: =VLOOKUP(C15,[15]Sheet1!$B$40:$F$71,5,0) -> Kecil | K15: =VLOOKUP(C15,'Data Lokasi'!$C$203:$S$1681,17,0) -> 44340 | L15: =VLOOKUP(C15,'Data Lokasi'!$C$203:$X$1681,21,0) -> 0 | M15: =VLOOKUP(C15,'Data Lokasi'!$C$203:$X$1681,22,0) -> 0
B16: W03 | C16: 072H1 | D16: =VLOOKUP(C16,'Data Lokasi'!$C$203:$D$1681,2,0) -> 10.52 | E16: =VLOOKUP(C16,'Data Lokasi'!$C$203:$S$1681,5,0) -> 44316 | F16: =VLOOKUP(C16,'Data Lokasi'!$C$203:$S$1681,9,0) -> 44333 | G16: =VLOOKUP(C16,'Data Lokasi'!$C$203:$S$1681,7,0) -> 44367 | H16: =MAX(F16:G16)+1 -> 44368 | I16: =VLOOKUP(C16,[15]Sheet1!$B$40:$F$71,4,0) -> Crown | J16: =VLOOKUP(C16,[15]Sheet1!$B$40:$F$71,5,0) -> Kecil | K16: =VLOOKUP(C16,'Data Lokasi'!$C$203:$S$1681,17,0) -> 44362 | L16: =VLOOKUP(C16,'Data Lokasi'!$C$203:$X$1681,21,0) -> 0 | M16: =VLOOKUP(C16,'Data Lokasi'!$C$203:$X$1681,22,0) -> 0 | N16: 0
B17: W03 | C17: 073C | D17: =VLOOKUP(C17,'Data Lokasi'!$C$203:$D$1681,2,0) -> 6.56 | E17: =VLOOKUP(C17,'Data Lokasi'!$C$203:$S$1681,5,0) -> 44322 | F17: =VLOOKUP(C17,'Data Lokasi'!$C$203:$S$1681,9,0) -> 44344 | G17: =VLOOKUP(C17,'Data Lokasi'!$C$203:$S$1681,7,0) -> 44367 | H17: =MAX(F17:G17)+1 -> 44368 | I17: =VLOOKUP(C17,[15]Sheet1!$B$40:$F$71,4,0) -> Crown | J17: =VLOOKUP(C17,[15]Sheet1!$B$40:$F$71,5,0) -> Kecil | K17: =VLOOKUP(C17,'Data Lokasi'!$C$203:$S$1681,17,0) -> 44349 | L17: =VLOOKUP(C17,'Data Lokasi'!$C$203:$X$1681,21,0) -> 0 | M17: =VLOOKUP(C17,'Data Lokasi'!$C$203:$X$1681,22,0) -> 0 | N17: 0
B18: W03 | C18: 073E | D18: =VLOOKUP(C18,'Data Lokasi'!$C$203:$D$1681,2,0) -> 8.28 | E18: =VLOOKUP(C18,'Data Lokasi'!$C$203:$S$1681,5,0) -> 44324 | F18: =VLOOKUP(C18,'Data Lokasi'!$C$203:$S$1681,9,0) -> 44344 | G18: =VLOOKUP(C18,'Data Lokasi'!$C$203:$S$1681,7,0) -> 44367 | H18: =MAX(F18:G18)+1 -> 44368 | I18: =VLOOKUP(C18,[15]Sheet1!$B$40:$F$71,4,0) -> Crown | J18: =VLOOKUP(C18,[15]Sheet1!$B$40:$F$71,5,0) -> Kecil | K18: =VLOOKUP(C18,'Data Lokasi'!$C$203:$S$1681,17,0) -> 44357 | L18: =VLOOKUP(C18,'Data Lokasi'!$C$203:$X$1681,21,0) -> 0 | M18: =VLOOKUP(C18,'Data Lokasi'!$C$203:$X$1681,22,0) -> 0 | N18: 0
B19: W03 | C19: 073L | D19: =VLOOKUP(C19,'Data Lokasi'!$C$203:$D$1681,2,0) -> 11.91 | E19: =VLOOKUP(C19,'Data Lokasi'!$C$203:$S$1681,5,0) -> 44320 | F19: =VLOOKUP(C19,'Data Lokasi'!$C$203:$S$1681,9,0) -> 44340 | G19: =VLOOKUP(C19,'Data Lokasi'!$C$203:$S$1681,7,0) -> 44365 | H19: =MAX(F19:G19)+1 -> 44366 | I19: =VLOOKUP(C19,[15]Sheet1!$B$40:$F$71,4,0) -> Crown | J19: =VLOOKUP(C19,[15]Sheet1!$B$40:$F$71,5,0) -> Kecil | K19: =VLOOKUP(C19,'Data Lokasi'!$C$203:$S$1681,17,0) -> 44345 | L19: =VLOOKUP(C19,'Data Lokasi'!$C$203:$X$1681,21,0) -> 0 | M19: =VLOOKUP(C19,'Data Lokasi'!$C$203:$X$1681,22,0) -> 0 | N19: 0.5
